Workbook

Sheet الرئيسية
B1: لوحة التحكم
B2: ="النهارده: "&INDEX('حسابات'!$A$2:$A$8,MATCH(WEEKDAY(TODAY()),'حسابات'!$B$2:$B$8,0))&" "&DAY(TODAY())&"/"&MONTH(TODAY())&"/"&YEAR(TODAY()) -> النهارده: الجمعة 2/10/2026
B4: =SUM('حسابات'!$AG$2:$AG$181) -> 1 | D4: =MAX('المواعيد'!$J$5:$J$34) -> 0 | F4: ='حسابات'!$AC$181 -> 0 | H4: ='حسابات'!$AF$181 -> 0
B5: طالب | D5: حصص النهارده | F5: تنبيه غياب | H5: مصاريف متأخرة
B7: حصص النهارده
B8: الساعة | C8: المجموعة / الطالب | E8: المكان | G8: هنعمل إيه
B9: =IF($K9="","",INDEX('المواعيد'!$C$5:$C$34,$K9)) | C9: =IF($K9="","مفيش حصص متسجلة النهارده",INDEX('المواعيد'!$D$5:$D$34,$K9)) -> مفيش حصص متسجلة النهارده | E9: =IF($K9="","",IF(INDEX('المواعيد'!$E$5:$E$34,$K9)="","",INDEX('المواعيد'!$E$5:$E$34,$K9))) | G9: =IF($K9="","",IFERROR(INDEX('حسابات'!$P$2:$P$9,MATCH(INDEX('المواعيد'!$D$5:$D$34,$K9),'حسابات'!$J$2:$J$9,0)),"")) | K9: =IFERROR(MATCH(1,'المواعيد'!$J$5:$J$34,0),"")
B10: =IF($K10="","",INDEX('المواعيد'!$C$5:$C$34,$K10)) | C10: =IF($K10="","",INDEX('المواعيد'!$D$5:$D$34,$K10)) | E10: =IF($K10="","",IF(INDEX('المواعيد'!$E$5:$E$34,$K10)="","",INDEX('المواعيد'!$E$5:$E$34,$K10))) | G10: =IF($K10="","",IFERROR(INDEX('حسابات'!$P$2:$P$9,MATCH(INDEX('المواعيد'!$D$5:$D$34,$K10),'حسابات'!$J$2:$J$9,0)),"")) | K10: =IFERROR(MATCH(2,'المواعيد'!$J$5:$J$34,0),"")
B11: =IF($K11="","",INDEX('المواعيد'!$C$5:$C$34,$K11)) | C11: =IF($K11="","",INDEX('المواعيد'!$D$5:$D$34,$K11)) | E11: =IF($K11="","",IF(INDEX('المواعيد'!$E$5:$E$34,$K11)="","",INDEX('المواعيد'!$E$5:$E$34,$K11))) | G11: =IF($K11="","",IFERROR(INDEX('حسابات'!$P$2:$P$9,MATCH(INDEX('المواعيد'!$D$5:$D$34,$K11),'حسابات'!$J$2:$J$9,0)),"")) | K11: =IFERROR(MATCH(3,'المواعيد'!$J$5:$J$34,0),"")
B12: =IF($K12="","",INDEX('المواعيد'!$C$5:$C$34,$K12)) | C12: =IF($K12="","",INDEX('المواعيد'!$D$5:$D$34,$K12)) | E12: =IF($K12="","",IF(INDEX('المواعيد'!$E$5:$E$34,$K12)="","",INDEX('المواعيد'!$E$5:$E$34,$K12))) | G12: =IF($K12="","",IFERROR(INDEX('حسابات'!$P$2:$P$9,MATCH(INDEX('المواعيد'!$D$5:$D$34,$K12),'حسابات'!$J$2:$J$9,0)),"")) | K12: =IFERROR(MATCH(4,'المواعيد'!$J$5:$J$34,0),"")
B13: =IF($K13="","",INDEX('المواعيد'!$C$5:$C$34,$K13)) | C13: =IF($K13="","",INDEX('المواعيد'!$D$5:$D$34,$K13)) | E13: =IF($K13="","",IF(INDEX('المواعيد'!$E$5:$E$34,$K13)="","",INDEX('المواعيد'!$E$5:$E$34,$K13))) | G13: =IF($K13="","",IFERROR(INDEX('حسابات'!$P$2:$P$9,MATCH(INDEX('المواعيد'!$D$5:$D$34,$K13),'حسابات'!$J$2:$J$9,0)),"")) | K13: =IFERROR(MATCH(5,'المواعيد'!$J$5:$J$34,0),"")
B14: =IF($K14="","",INDEX('المواعيد'!$C$5:$C$34,$K14)) | C14: =IF($K14="","",INDEX('المواعيد'!$D$5:$D$34,$K14)) | E14: =IF($K14="","",IF(INDEX('المواعيد'!$E$5:$E$34,$K14)="","",INDEX('المواعيد'!$E$5:$E$34,$K14))) | G14: =IF($K14="","",IFERROR(INDEX('حسابات'!$P$2:$P$9,MATCH(INDEX('المواعيد'!$D$5:$D$34,$K14),'حسابات'!$J$2:$J$9,0)),"")) | K14: =IFERROR(MATCH(6,'المواعيد'!$J$5:$J$34,0),"")
B16: الحصة الجاية لكل مجموعة
B17: المجموعة | D17: الميعاد | F17: هنعمل إيه
B18: =IF($K18="","",INDEX('حسابات'!$J$2:$J$9,$K18)&CHAR(10)&INDEX('حسابات'!$O$2:$O$9,$K18)) -> مجموعة 1 لسه ما بدأتش | D18: =IF($K18="","",IF(INDEX('حسابات'!$S$2:$S$9,$K18)="","—",INDEX('حسابات'!$S$2:$S$9,$K18))) -> بكرة 3/10 – 5:00 م | F18: =IF($K18="","",INDEX('حسابات'!$P$2:$P$9,$K18)) | K18: =IFERROR(MATCH(1,'حسابات'!$U$2:$U$9,0),"") -> 1
B19: =IF($K19="","",INDEX('حسابات'!$J$2:$J$9,$K19)&CHAR(10)&INDEX('حسابات'!$O$2:$O$9,$K19)) | D19: =IF($K19="","",IF(INDEX('حسابات'!$S$2:$S$9,$K19)="","—",INDEX('حسابات'!$S$2:$S$9,$K19))) | F19: =IF($K19="","",INDEX('حسابات'!$P$2:$P$9,$K19)) | K19: =IFERROR(MATCH(2,'حسابات'!$U$2:$U$9,0),"")
B20: =IF($K20="","",INDEX('حسابات'!$J$2:$J$9,$K20)&CHAR(10)&INDEX('حسابات'!$O$2:$O$9,$K20)) | D20: =IF($K20="","",IF(INDEX('حسابات'!$S$2:$S$9,$K20)="","—",INDEX('حسابات'!$S$2:$S$9,$K20))) | F20: =IF($K20="","",INDEX('حسابات'!$P$2:$P$9,$K20)) | K20: =IFERROR(MATCH(3,'حسابات'!$U$2:$U$9,0),"")
B21: =IF($K21="","",INDEX('حسابات'!$J$2:$J$9,$K21)&CHAR(10)&INDEX('حسابات'!$O$2:$O$9,$K21)) | D21: =IF($K21="","",IF(INDEX('حسابات'!$S$2:$S$9,$K21)="","—",INDEX('حسابات'!$S$2:$S$9,$K21))) | F21: =IF($K21="","",INDEX('حسابات'!$P$2:$P$9,$K21)) | K21: =IFERROR(MATCH(4,'حسابات'!$U$2:$U$9,0),"")
B22: =IF($K22="","",INDEX('حسابات'!$J$2:$J$9,$K22)&CHAR(10)&INDEX('حسابات'!$O$2:$O$9,$K22)) | D22: =IF($K22="","",IF(INDEX('حسابات'!$S$2:$S$9,$K22)="","—",INDEX('حسابات'!$S$2:$S$9,$K22))) | F22: =IF($K22="","",INDEX('حسابات'!$P$2:$P$9,$K22)) | K22: =IFERROR(MATCH(5,'حسابات'!$U$2:$U$9,0),"")
B23: =IF($K23="","",INDEX('حسابات'!$J$2:$J$9,$K23)&CHAR(10)&INDEX('حسابات'!$O$2:$O$9,$K23)) | D23: =IF($K23="","",IF(INDEX('حسابات'!$S$2:$S$9,$K23)="","—",INDEX('حسابات'!$S$2:$S$9,$K23))) | F23: =IF($K23="","",INDEX('حسابات'!$P$2:$P$9,$K23)) | K23: =IFERROR(MATCH(6,'حسابات'!$U$2:$U$9,0),"")
B24: =IF($K24="","",INDEX('حسابات'!$J$2:$J$9,$K24)&CHAR(10)&INDEX('حسابات'!$O$2:$O$9,$K24)) | D24: =IF($K24="","",IF(INDEX('حسابات'!$S$2:$S$9,$K24)="","—",INDEX('حسابات'!$S$2:$S$9,$K24))) | F24: =IF($K24="","",INDEX('حسابات'!$P$2:$P$9,$K24)) | K24: =IFERROR(MATCH(7,'حسابات'!$U$2:$U$9,0),"")
B25: =IF($K25="","",INDEX('حسابات'!$J$2:$J$9,$K25)&CHAR(10)&INDEX('حسابات'!$O$2:$O$9,$K25)) | D25: =IF($K25="","",IF(INDEX('حسابات'!$S$2:$S$9,$K25)="","—",INDEX('حسابات'!$S$2:$S$9,$K25))) | F25: =IF($K25="","",INDEX('حسابات'!$P$2:$P$9,$K25)) | K25: =IFERROR(MATCH(8,'حسابات'!$U$2:$U$9,0),"")
B27: تنبيه الغياب (آخر 8 حصص) | F27: التنبيه من كام مرة؟ | H27: 2
B28: الطالب | E28: غياب | F28: المجموعة | H28: ولي الأمر
B29: =IF($K29="","",INDEX('حسابات'!$Y$2:$Y$181,$K29)) | E29: =IF($K29="","",INDEX('حسابات'!$AA$2:$AA$181,$K29)) | F29: =IF($K29="","",INDEX('حسابات'!$X$2:$X$181,$K29)) | H29: =IF($K29="","",INDEX('حسابات'!$Z$2:$Z$181,$K29)) | K29: =IFERROR(MATCH(1,'حسابات'!$AC$2:$AC$181,0),"")
B30: =IF($K30="","",INDEX('حسابات'!$Y$2:$Y$181,$K30)) | E30: =IF($K30="","",INDEX('حسابات'!$AA$2:$AA$181,$K30)) | F30: =IF($K30="","",INDEX('حسابات'!$X$2:$X$181,$K30)) | H30: =IF($K30="","",INDEX('حسابات'!$Z$2:$Z$181,$K30)) | K30: =IFERROR(MATCH(2,'حسابات'!$AC$2:$AC$181,0),"")
B31: =IF($K31="","",INDEX('حسابات'!$Y$2:$Y$181,$K31)) | E31: =IF($K31="","",INDEX('حسابات'!$AA$2:$AA$181,$K31)) | F31: =IF($K31="","",INDEX('حسابات'!$X$2:$X$181,$K31)) | H31: =IF($K31="","",INDEX('حسابات'!$Z$2:$Z$181,$K31)) | K31: =IFERROR(MATCH(3,'حسابات'!$AC$2:$AC$181,0),"")
B32: =IF($K32="","",INDEX('حسابات'!$Y$2:$Y$181,$K32)) | E32: =IF($K32="","",INDEX('حسابات'!$AA$2:$AA$181,$K32)) | F32: =IF($K32="","",INDEX('حسابات'!$X$2:$X$181,$K32)) | H32: =IF($K32="","",INDEX('حسابات'!$Z$2:$Z$181,$K32)) | K32: =IFERROR(MATCH(4,'حسابات'!$AC$2:$AC$181,0),"")
B33: =IF($K33="","",INDEX('حسابات'!$Y$2:$Y$181,$K33)) | E33: =IF($K33="","",INDEX('حسابات'!$AA$2:$AA$181,$K33)) | F33: =IF($K33="","",INDEX('حسابات'!$X$2:$X$181,$K33)) | H33: =IF($K33="","",INDEX('حسابات'!$Z$2:$Z$181,$K33)) | K33: =IFERROR(MATCH(5,'حسابات'!$AC$2:$AC$181,0),"")
B34: =IF($K34="","",INDEX('حسابات'!$Y$2:$Y$181,$K34)) | E34: =IF($K34="","",INDEX('حسابات'!$AA$2:$AA$181,$K34)) | F34: =IF($K34="","",INDEX('حسابات'!$X$2:$X$181,$K34)) | H34: =IF($K34="","",INDEX('حسابات'!$Z$2:$Z$181,$K34)) | K34: =IFERROR(MATCH(6,'حسابات'!$AC$2:$AC$181,0),"")
B35: =IF($K35="","",INDEX('حسابات'!$Y$2:$Y$181,$K35)) | E35: =IF($K35="","",INDEX('حسابات'!$AA$2:$AA$181,$K35)) | F35: =IF($K35="","",INDEX('حسابات'!$X$2:$X$181,$K35)) | H35: =IF($K35="","",INDEX('حسابات'!$Z$2:$Z$181,$K35)) | K35: =IFERROR(MATCH(7,'حسابات'!$AC$2:$AC$181,0),"")
B36: =IF($K36="","",INDEX('حسابات'!$Y$2:$Y$181,$K36)) | E36: =IF($K36="","",INDEX('حسابات'!$AA$2:$AA$181,$K36)) | F36: =IF($K36="","",INDEX('حسابات'!$X$2:$X$181,$K36)) | H36: =IF($K36="","",INDEX('حسابات'!$Z$2:$Z$181,$K36)) | K36: =IFERROR(MATCH(8,'حسابات'!$AC$2:$AC$181,0),"")
B37: =IF($K37="","",INDEX('حسابات'!$Y$2:$Y$181,$K37)) | E37: =IF($K37="","",INDEX('حسابات'!$AA$2:$AA$181,$K37)) | F37: =IF($K37="","",INDEX('حسابات'!$X$2:$X$181,$K37)) | H37: =IF($K37="","",INDEX('حسابات'!$Z$2:$Z$181,$K37)) | K37: =IFERROR(MATCH(9,'حسابات'!$AC$2:$AC$181,0),"")
B38: =IF($K38="","",INDEX('حسابات'!$Y$2:$Y$181,$K38)) | E38: =IF($K38="","",INDEX('حسابات'!$AA$2:$AA$181,$K38)) | F38: =IF($K38="","",INDEX('حسابات'!$X$2:$X$181,$K38)) | H38: =IF($K38="","",INDEX('حسابات'!$Z$2:$Z$181,$K38)) | K38: =IFERROR(MATCH(10,'حسابات'!$AC$2:$AC$181,0),"")
B39: =IF('حسابات'!$AC$181>10,"+ "&('حسابات'!$AC$181-10)&" كمان · عمود «غياب» في صفحات المجموعات",IF('حسابات'!$AC$181=0,"مفيش تنبيهات غياب","")) -> مفيش تنبيهات غياب
B41: مصاريف متأخرة
B42: الطالب | E42: المطلوب | F42: المجموعة | H42: ولي الأمر
B43: =IF($K43="","",INDEX('حسابات'!$Y$2:$Y$181,$K43)) | E43: =IF($K43="","",INDEX('حسابات'!$AD$2:$AD$181,$K43)) | F43: =IF($K43="","",INDEX('حسابات'!$X$2:$X$181,$K43)) | H43: =IF($K43="","",INDEX('حسابات'!$Z$2:$Z$181,$K43)) | K43: =IFERROR(MATCH(1,'حسابات'!$AF$2:$AF$181,0),"")
B44: =IF($K44="","",INDEX('حسابات'!$Y$2:$Y$181,$K44)) | E44: =IF($K44="","",INDEX('حسابات'!$AD$2:$AD$181,$K44)) | F44: =IF($K44="","",INDEX('حسابات'!$X$2:$X$181,$K44)) | H44: =IF($K44="","",INDEX('حسابات'!$Z$2:$Z$181,$K44)) | K44: =IFERROR(MATCH(2,'حسابات'!$AF$2:$AF$181,0),"")
B45: =IF($K45="","",INDEX('حسابات'!$Y$2:$Y$181,$K45)) | E45: =IF($K45="","",INDEX('حسابات'!$AD$2:$AD$181,$K45)) | F45: =IF($K45="","",INDEX('حسابات'!$X$2:$X$181,$K45)) | H45: =IF($K45="","",INDEX('حسابات'!$Z$2:$Z$181,$K45)) | K45: =IFERROR(MATCH(3,'حسابات'!$AF$2:$AF$181,0),"")
...

Sheet المواعيد
A1: جدول المواعيد الأسبوعي
A2: صف لكل ميعاد ثابت. المجموعة اللي بتيجي مرتين في الأسبوع تتكتب في صفين.
A4: م | B4: اليوم | C4: الساعة | D4: المجموعة / الطالب | E4: المكان / ملاحظات
A5: 1 | B5: السبت | C5: 5:00 م | D5: مجموعة 1 | E5: مثال، عدّليه | G5: =IF($B5="",0,IFERROR(INDEX('حسابات'!$B$2:$B$8,MATCH($B5,'حسابات'!$A$2:$A$8,0)),0)) -> 7 | H5: =IF($C5="",99,IFERROR(MATCH($C5,'حسابات'!$D$2:$D$35,0),99)) -> 21 | I5: =IF(AND($G5>0,$G5=WEEKDAY(TODAY())),1,0) -> 0 | J5: =IF($I5=1,COUNTIFS($I$5:$I$34,1,$H$5:$H$34,"<"&$H5)+COUNTIFS($I$5:$I5,1,$H$5:$H5,$H5),"") | K5: =IF($G5=0,7,MOD($G5-WEEKDAY(TODAY()),7)) -> 1 | L5: =IF($K5=0,7,$K5) -> 1
A6: 2 | G6: =IF($B6="",0,IFERROR(INDEX('حسابات'!$B$2:$B$8,MATCH($B6,'حسابات'!$A$2:$A$8,0)),0)) -> 0 | H6: =IF($C6="",99,IFERROR(MATCH($C6,'حسابات'!$D$2:$D$35,0),99)) -> 99 | I6: =IF(AND($G6>0,$G6=WEEKDAY(TODAY())),1,0) -> 0 | J6: =IF($I6=1,COUNTIFS($I$5:$I$34,1,$H$5:$H$34,"<"&$H6)+COUNTIFS($I$5:$I6,1,$H$5:$H6,$H6),"") | K6: =IF($G6=0,7,MOD($G6-WEEKDAY(TODAY()),7)) -> 7 | L6: =IF($K6=0,7,$K6) -> 7
A7: 3 | G7: =IF($B7="",0,IFERROR(INDEX('حسابات'!$B$2:$B$8,MATCH($B7,'حسابات'!$A$2:$A$8,0)),0)) -> 0 | H7: =IF($C7="",99,IFERROR(MATCH($C7,'حسابات'!$D$2:$D$35,0),99)) -> 99 | I7: =IF(AND($G7>0,$G7=WEEKDAY(TODAY())),1,0) -> 0 | J7: =IF($I7=1,COUNTIFS($I$5:$I$34,1,$H$5:$H$34,"<"&$H7)+COUNTIFS($I$5:$I7,1,$H$5:$H7,$H7),"") | K7: =IF($G7=0,7,MOD($G7-WEEKDAY(TODAY()),7)) -> 7 | L7: =IF($K7=0,7,$K7) -> 7
A8: 4 | G8: =IF($B8="",0,IFERROR(INDEX('حسابات'!$B$2:$B$8,MATCH($B8,'حسابات'!$A$2:$A$8,0)),0)) -> 0 | H8: =IF($C8="",99,IFERROR(MATCH($C8,'حسابات'!$D$2:$D$35,0),99)) -> 99 | I8: =IF(AND($G8>0,$G8=WEEKDAY(TODAY())),1,0) -> 0 | J8: =IF($I8=1,COUNTIFS($I$5:$I$34,1,$H$5:$H$34,"<"&$H8)+COUNTIFS($I$5:$I8,1,$H$5:$H8,$H8),"") | K8: =IF($G8=0,7,MOD($G8-WEEKDAY(TODAY()),7)) -> 7 | L8: =IF($K8=0,7,$K8) -> 7
A9: 5 | G9: =IF($B9="",0,IFERROR(INDEX('حسابات'!$B$2:$B$8,MATCH($B9,'حسابات'!$A$2:$A$8,0)),0)) -> 0 | H9: =IF($C9="",99,IFERROR(MATCH($C9,'حسابات'!$D$2:$D$35,0),99)) -> 99 | I9: =IF(AND($G9>0,$G9=WEEKDAY(TODAY())),1,0) -> 0 | J9: =IF($I9=1,COUNTIFS($I$5:$I$34,1,$H$5:$H$34,"<"&$H9)+COUNTIFS($I$5:$I9,1,$H$5:$H9,$H9),"") | K9: =IF($G9=0,7,MOD($G9-WEEKDAY(TODAY()),7)) -> 7 | L9: =IF($K9=0,7,$K9) -> 7
A10: 6 | G10: =IF($B10="",0,IFERROR(INDEX('حسابات'!$B$2:$B$8,MATCH($B10,'حسابات'!$A$2:$A$8,0)),0)) -> 0 | H10: =IF($C10="",99,IFERROR(MATCH($C10,'حسابات'!$D$2:$D$35,0),99)) -> 99 | I10: =IF(AND($G10>0,$G10=WEEKDAY(TODAY())),1,0) -> 0 | J10: =IF($I10=1,COUNTIFS($I$5:$I$34,1,$H$5:$H$34,"<"&$H10)+COUNTIFS($I$5:$I10,1,$H$5:$H10,$H10),"") | K10: =IF($G10=0,7,MOD($G10-WEEKDAY(TODAY()),7)) -> 7 | L10: =IF($K10=0,7,$K10) -> 7
A11: 7 | G11: =IF($B11="",0,IFERROR(INDEX('حسابات'!$B$2:$B$8,MATCH($B11,'حسابات'!$A$2:$A$8,0)),0)) -> 0 | H11: =IF($C11="",99,IFERROR(MATCH($C11,'حسابات'!$D$2:$D$35,0),99)) -> 99 | I11: =IF(AND($G11>0,$G11=WEEKDAY(TODAY())),1,0) -> 0 | J11: =IF($I11=1,COUNTIFS($I$5:$I$34,1,$H$5:$H$34,"<"&$H11)+COUNTIFS($I$5:$I11,1,$H$5:$H11,$H11),"") | K11: =IF($G11=0,7,MOD($G11-WEEKDAY(TODAY()),7)) -> 7 | L11: =IF($K11=0,7,$K11) -> 7
A12: 8 | G12: =IF($B12="",0,IFERROR(INDEX('حسابات'!$B$2:$B$8,MATCH($B12,'حسابات'!$A$2:$A$8,0)),0)) -> 0 | H12: =IF($C12="",99,IFERROR(MATCH($C12,'حسابات'!$D$2:$D$35,0),99)) -> 99 | I12: =IF(AND($G12>0,$G12=WEEKDAY(TODAY())),1,0) -> 0 | J12: =IF($I12=1,COUNTIFS($I$5:$I$34,1,$H$5:$H$34,"<"&$H12)+COUNTIFS($I$5:$I12,1,$H$5:$H12,$H12),"") | K12: =IF($G12=0,7,MOD($G12-WEEKDAY(TODAY()),7)) -> 7 | L12: =IF($K12=0,7,$K12) -> 7
A13: 9 | G13: =IF($B13="",0,IFERROR(INDEX('حسابات'!$B$2:$B$8,MATCH($B13,'حسابات'!$A$2:$A$8,0)),0)) -> 0 | H13: =IF($C13="",99,IFERROR(MATCH($C13,'حسابات'!$D$2:$D$35,0),99)) -> 99 | I13: =IF(AND($G13>0,$G13=WEEKDAY(TODAY())),1,0) -> 0 | J13: =IF($I13=1,COUNTIFS($I$5:$I$34,1,$H$5:$H$34,"<"&$H13)+COUNTIFS($I$5:$I13,1,$H$5:$H13,$H13),"") | K13: =IF($G13=0,7,MOD($G13-WEEKDAY(TODAY()),7)) -> 7 | L13: =IF($K13=0,7,$K13) -> 7
A14: 10 | G14: =IF($B14="",0,IFERROR(INDEX('حسابات'!$B$2:$B$8,MATCH($B14,'حسابات'!$A$2:$A$8,0)),0)) -> 0 | H14: =IF($C14="",99,IFERROR(MATCH($C14,'حسابات'!$D$2:$D$35,0),99)) -> 99 | I14: =IF(AND($G14>0,$G14=WEEKDAY(TODAY())),1,0) -> 0 | J14: =IF($I14=1,COUNTIFS($I$5:$I$34,1,$H$5:$H$34,"<"&$H14)+COUNTIFS($I$5:$I14,1,$H$5:$H14,$H14),"") | K14: =IF($G14=0,7,MOD($G14-WEEKDAY(TODAY()),7)) -> 7 | L14: =IF($K14=0,7,$K14) -> 7
A15: 11 | G15: =IF($B15="",0,IFERROR(INDEX('حسابات'!$B$2:$B$8,MATCH($B15,'حسابات'!$A$2:$A$8,0)),0)) -> 0 | H15: =IF($C15="",99,IFERROR(MATCH($C15,'حسابات'!$D$2:$D$35,0),99)) -> 99 | I15: =IF(AND($G15>0,$G15=WEEKDAY(TODAY())),1,0) -> 0 | J15: =IF($I15=1,COUNTIFS($I$5:$I$34,1,$H$5:$H$34,"<"&$H15)+COUNTIFS($I$5:$I15,1,$H$5:$H15,$H15),"") | K15: =IF($G15=0,7,MOD($G15-WEEKDAY(TODAY()),7)) -> 7 | L15: =IF($K15=0,7,$K15) -> 7
A16: 12 | G16: =IF($B16="",0,IFERROR(INDEX('حسابات'!$B$2:$B$8,MATCH($B16,'حسابات'!$A$2:$A$8,0)),0)) -> 0 | H16: =IF($C16="",99,IFERROR(MATCH($C16,'حسابات'!$D$2:$D$35,0),99)) -> 99 | I16: =IF(AND($G16>0,$G16=WEEKDAY(TODAY())),1,0) -> 0 | J16: =IF($I16=1,COUNTIFS($I$5:$I$34,1,$H$5:$H$34,"<"&$H16)+COUNTIFS($I$5:$I16,1,$H$5:$H16,$H16),"") | K16: =IF($G16=0,7,MOD($G16-WEEKDAY(TODAY()),7)) -> 7 | L16: =IF($K16=0,7,$K16) -> 7
A17: 13 | G17: =IF($B17="",0,IFERROR(INDEX('حسابات'!$B$2:$B$8,MATCH($B17,'حسابات'!$A$2:$A$8,0)),0)) -> 0 | H17: =IF($C17="",99,IFERROR(MATCH($C17,'حسابات'!$D$2:$D$35,0),99)) -> 99 | I17: =IF(AND($G17>0,$G17=WEEKDAY(TODAY())),1,0) -> 0 | J17: =IF($I17=1,COUNTIFS($I$5:$I$34,1,$H$5:$H$34,"<"&$H17)+COUNTIFS($I$5:$I17,1,$H$5:$H17,$H17),"") | K17: =IF($G17=0,7,MOD($G17-WEEKDAY(TODAY()),7)) -> 7 | L17: =IF($K17=0,7,$K17) -> 7
... A34: 30 | G34: =IF($B34="",0,IFERROR(INDEX('حسابات'!$B$2:$B$8,MATCH($B34,'حسابات'!$A$2:$A$8,0)),0)) -> 0 | H34: =IF($C34="",99,IFERROR(MATCH($C34,'حسابات'!$D$2:$D$35,0),99)) -> 99 | I34: =IF(AND($G34>0,$G34=WEEKDAY(TODAY())),1,0) -> 0 | J34: =IF($I34=1,COUNTIFS($I$5:$I$34,1,$H$5:$H$34,"<"&$H34)+COUNTIFS($I$5:$I34,1,$H$5:$H34,$H34),"") | K34: =IF($G34=0,7,MOD($G34-WEEKDAY(TODAY()),7)) -> 7 | L34: =IF($K34=0,7,$K34) -> 7

Sheet مجموعة 1
A1: مجموعة 1 | C1: ="عدد الطلاب: "&$HE$1&CHAR(10)&"الغياب والواجب الناقص: في آخر 8 حصص" -> عدد الطلاب: 1 الغياب والواجب الناقص: في آخر 8 حصص | G1: الشهر 1 | X1: الشهر 2 | AO1: الشهر 3 | BF1: الشهر 4 | BW1: الشهر 5 | CN1: الشهر 6 | DE1: الشهر 7 | DV1: الشهر 8 | EM1: الشهر 9 | FD1: الشهر 10 | FU1: الشهر 11 | GL1: الشهر 12 | HC1: =SUMPRODUCT(MAX(($G$4:$HB$4="ح")*($G$20:$HB$20>0)*$G$47:$HB$47)) -> 0 | HD1: =IF(OR($F$27="",$F$27="الكل"),1,IFERROR(MATCH($F$27,'حسابات'!$F$2:$F$14,0)-1,1)) -> 1 | HE1: =SUMPRODUCT(--($B$5:$B$19<>"")) -> 1 | HF1: =IF($HE$3=0,"",8-$HE$3) -> 1 | HG1: ='الرئيسية'!$H$27 -> 2
A2: =IF($HC$1=0,"لسه ما بدأتش",IF(INDEX($G$1:$HB$1,1,17*($HC$2-1)+1)="","شهر "&$HC$2,INDEX($G$1:$HB$1,1,17*($HC$2-1)+1))&" · حصة "&$HC$3&" من 8") -> لسه ما بدأتش | G2: حصة 1 | I2: حصة 2 | K2: حصة 3 | M2: حصة 4 | O2: حصة 5 | Q2: حصة 6 | S2: حصة 7 | U2: حصة 8 | W2: المصاريف | X2: حصة 1 | Z2: حصة 2 | AB2: حصة 3 | AD2: حصة 4 | AF2: حصة 5 | AH2: حصة 6 | AJ2: حصة 7 | AL2: حصة 8 | AN2: المصاريف | AO2: حصة 1 | AQ2: حصة 2 | AS2: حصة 3 | AU2: حصة 4 | AW2: حصة 5 | AY2: حصة 6 | BA2: حصة 7 | BC2: حصة 8 | BE2: المصاريف | BF2: حصة 1 | BH2: حصة 2 | BJ2: حصة 3 | BL2: حصة 4 | BN2: حصة 5 | BP2: حصة 6 | BR2: حصة 7 | BT2: حصة 8 | BV2: المصاريف | BW2: حصة 1 | BY2: حصة 2 | CA2: حصة 3 | CC2: حصة 4 | CE2: حصة 5 | CG2: حصة 6 | CI2: حصة 7 | CK2: حصة 8 | CM2: المصاريف | CN2: حصة 1 | CP2: حصة 2 | CR2: حصة 3 | CT2: حصة 4 | CV2: حصة 5 | CX2: حصة 6 | CZ2: حصة 7 | DB2: حصة 8 | DD2: المصاريف | DE2: حصة 1 | DG2: حصة 2 | DI2: حصة 3 | DK2: حصة 4 | DM2: حصة 5 | DO2: حصة 6 | DQ2: حصة 7 | DS2: حصة 8 | DU2: المصاريف | DV2: حصة 1 | DX2: حصة 2 | DZ2: حصة 3 | EB2: حصة 4 | ED2: حصة 5 | EF2: حصة 6 | EH2: حصة 7 | EJ2: حصة 8 | EL2: المصاريف | EM2: حصة 1 | EO2: حصة 2 | EQ2: حصة 3 | ES2: حصة 4 | EU2: حصة 5 | EW2: حصة 6 | EY2: حصة 7 | FA2: حصة 8 | FC2: المصاريف | FD2: حصة 1 | FF2: حصة 2 | FH2: حصة 3 | FJ2: حصة 4 | FL2: حصة 5 | FN2: حصة 6 | FP2: حصة 7 | FR2: حصة 8 | FT2: المصاريف | FU2: حصة 1 | FW2: حصة 2 | FY2: حصة 3 | GA2: حصة 4 | GC2: حصة 5 | GE2: حصة 6 | GG2: حصة 7 | GI2: حصة 8 | GK2: المصاريف | GL2: حصة 1 | GN2: حصة 2 | GP2: حصة 3 | GR2: حصة 4 | GT2: حصة 5 | GV2: حصة 6 | GX2: حصة 7 | GZ2: حصة 8 | HB2: المصاريف | HC2: =IF($HC$1=0,1,INT(($HC$1-1)/8)+1) -> 1 | HD2: =IF(OR($F$27="",$F$27="الكل"),12,$HD$1) -> 12 | HE2: =IF(SUMPRODUCT(($G$3:$HB$3=TODAY())*($G$20:$HB$20>0))>0,1,0) -> 0 | HF2: =IF($HF$1="","",TODAY()+$HF$1) -> 46298
HC3: =$HC$1-8*($HC$2-1) -> 0 | HE3: =IF($A$1="",0,IF($HE$2=1,SUMPRODUCT(MAX(('المواعيد'!$D$5:$D$34=$A$1)*(8-'المواعيد'!$L$5:$L$34))),SUMPRODUCT(MAX(('المواعيد'!$D$5:$D$34=$A$1)*(8-'المواعيد'!$K$5:$K$34))))) -> 7 | HF3: =IF($HF$1="",0,SUMPRODUCT(MAX(('المواعيد'!$D$5:$D$34=$A$1)*('المواعيد'!$G$5:$G$34=WEEKDAY($HF$2))*(ROW('المواعيد'!$D$5:$D$34)-4)))) -> 1
A4: م | B4: الاسم | C4: ولي الأمر | D4: غياب | E4: واجب | F4: المصاريف | G4: ح | H4: و | I4: ح | J4: و | K4: ح | L4: و | M4: ح | N4: و | O4: ح | P4: و | Q4: ح | R4: و | S4: ح | T4: و | U4: ح | V4: و | W4: دفع | X4: ح | Y4: و | Z4: ح | AA4: و | AB4: ح | AC4: و | AD4: ح | AE4: و | AF4: ح | AG4: و | AH4: ح | AI4: و | AJ4: ح | AK4: و | AL4: ح | AM4: و | AN4: دفع | AO4: ح | AP4: و | AQ4: ح | AR4: و | AS4: ح | AT4: و | AU4: ح | AV4: و | AW4: ح | AX4: و | AY4: ح | AZ4: و | BA4: ح | BB4: و | BC4: ح | BD4: و | BE4: دفع | BF4: ح | BG4: و | BH4: ح | BI4: و | BJ4: ح | BK4: و | BL4: ح | BM4: و | BN4: ح | BO4: و | BP4: ح | BQ4: و | BR4: ح | BS4: و | BT4: ح | BU4: و | BV4: دفع | BW4: ح | BX4: و | BY4: ح | BZ4: و | CA4: ح | CB4: و | CC4: ح | CD4: و | CE4: ح | CF4: و | CG4: ح | CH4: و | CI4: ح | CJ4: و | CK4: ح | CL4: و | CM4: دفع | CN4: ح | CO4: و | CP4: ح | CQ4: و | CR4: ح | CS4: و | CT4: ح | CU4: و | CV4: ح | CW4: و | CX4: ح | CY4: و | CZ4: ح | DA4: و | DB4: ح | DC4: و | DD4: دفع | DE4: ح | DF4: و | DG4: ح | DH4: و | DI4: ح | DJ4: و | DK4: ح | DL4: و | DM4: ح | DN4: و | DO4: ح | DP4: و | DQ4: ح | DR4: و | DS4: ح | DT4: و | DU4: دفع | DV4: ح | DW4: و | DX4: ح | DY4: و | DZ4: ح | EA4: و | EB4: ح | EC4: و | ED4: ح | EE4: و | EF4: ح | EG4: و | EH4: ح | EI4: و | EJ4: ح | EK4: و | EL4: دفع | EM4: ح | EN4: و | EO4: ح | EP4: و | EQ4: ح | ER4: و | ES4: ح | ET4: و | EU4: ح | EV4: و | EW4: ح | EX4: و | EY4: ح | EZ4: و | FA4: ح | FB4: و | FC4: دفع | FD4: ح | FE4: و | FF4: ح | FG4: و | FH4: ح | FI4: و | FJ4: ح | FK4: و | FL4: ح | FM4: و | FN4: ح | FO4: و | FP4: ح | FQ4: و | FR4: ح | FS4: و | FT4: دفع | FU4: ح | FV4: و | FW4: ح | FX4: و | FY4: ح | FZ4: و | GA4: ح | GB4: و | GC4: ح | GD4: و | GE4: ح | GF4: و | GG4: ح | GH4: و | GI4: ح | GJ4: و | GK4: دفع | GL4: ح | GM4: و | GN4: ح | GO4: و | GP4: ح | GQ4: و | GR4: ح | GS4: و | GT4: ح | GU4: و | GV4: ح | GW4: و | GX4: ح | GY4: و | GZ4: ح | HA4: و | HB4: دفع | HF4: =IF($HF$1="","",IF($HF$1=0,"النهارده",IF($HF$1=1,"بكرة",INDEX('حسابات'!$A$2:$A$8,MATCH(WEEKDAY($HF$2),'حسابات'!$B$2:$B$8,0))))&" "&DAY($HF$2)&"/"&MONTH($HF$2)&IF($HF$3=0,"",IF(INDEX('المواعيد'!$C$5:$C$34,$HF$3)="",""," – "&INDEX('المواعيد'!$C$5:$C$34,$HF$3)))) -> بكرة 3/10 – 5:00 م
A5: 1 | B5: مثال: أحمد محمد علي | C5: 01001234567 | D5: =IF($B5="","",IF($HC5=97,"-",IF($HD5=0,"متوقف",SUMPRODUCT(($G$4:$HB$4="ح")*($G$20:$HB$20>0)*($G5:$HB5<>TRUE)*($G$47:$HB$47>$HC$1-8)*($G$47:$HB$47>=$HC5))))) -> - | E5: =IF(OR($B5="",$HC5=97),"",SUMPRODUCT(($G$4:$HA$4="ح")*($G5:$HA5=TRUE)*($H5:$HB5<>TRUE)*($G$47:$HA$47>$HC$1-8))) | F5: =IF($B5="","",IF($HE5=0,IF($HC5=97,"-","تمام"),IF($HE5=1,IF(INDEX($G$1:$HB$1,1,17*($HF5-1)+1)="","شهر "&$HF5,INDEX($G$1:$HB$1,1,17*($HF5-1)+1)),IF($HE5=2,"شهرين",$HE5&" شهور")))) -> - | HC5: =97-SUMPRODUCT(MAX(($G$4:$HB$4="ح")*($G5:$HB5=TRUE)*(97-$G$47:$HB$47))) -> 97 | HD5: =SUMPRODUCT(($G$4:$HB$4="ح")*($G5:$HB5=TRUE)*($G$47:$HB$47>$HC$1-8)) -> 0 | HE5: =(COUNTIF($G5:$V5,TRUE)>0)*($W5<>TRUE)+(COUNTIF($X5:$AM5,TRUE)>0)*($AN5<>TRUE)+(COUNTIF($AO5:$BD5,TRUE)>0)*($BE5<>TRUE)+(COUNTIF($BF5:$BU5,TRUE)>0)*($BV5<>TRUE)+(COUNTIF($BW5:$CL5,TRUE)>0)*($CM5<>TRUE)+(COUNTIF($CN5:$DC5,TRUE)>0)*($DD5<>TRUE)+(COUNTIF($DE5:$DT5,TRUE)>0)*($DU5<>TRUE)+(COUNTIF($DV5:$EK5,TRUE)>0)*($EL5<>TRUE)+(COUNTIF($EM5:$FB5,TRUE)>0)*($FC5<>TRUE)+(COUNTIF($FD5:$FS5,TRUE)>0)*($FT5<>TRUE)+(COUNTIF($FU5:$GJ5,TRUE)>0)*($GK5<>TRUE)+(COUNTIF($GL5:$HA5,TRUE)>0)*($HB5<>TRUE) -> 0 | HF5: =IF($HE5=0,0,13-MAX((COUNTIF($G5:$V5,TRUE)>0)*($W5<>TRUE)*12,(COUNTIF($X5:$AM5,TRUE)>0)*($AN5<>TRUE)*11,(COUNTIF($AO5:$BD5,TRUE)>0)*($BE5<>TRUE)*10,(COUNTIF($BF5:$BU5,TRUE)>0)*($BV5<>TRUE)*9,(COUNTIF($BW5:$CL5,TRUE)>0)*($CM5<>TRUE)*8,(COUNTIF($CN5:$DC5,TRUE)>0)*($DD5<>TRUE)*7,(COUNTIF($DE5:$DT5,TRUE)>0)*($DU5<>TRUE)*6,(COUNTIF($DV5:$EK5,TRUE)>0)*($EL5<>TRUE)*5,(COUNTIF($EM5:$FB5,TRUE)>0)*($FC5<>TRUE)*4,(COUNTIF($FD5:$FS5,TRUE)>0)*($FT5<>TRUE)*3,(COUNTIF($FU5:$GJ5,TRUE)>0)*($GK5<>TRUE)*2,(COUNTIF($GL5:$HA5,TRUE)>0)*($HB5<>TRUE)*1)) -> 0
A6: 2 | D6: =IF($B6="","",IF($HC6=97,"-",IF($HD6=0,"متوقف",SUMPRODUCT(($G$4:$HB$4="ح")*($G$20:$HB$20>0)*($G6:$HB6<>TRUE)*($G$47:$HB$47>$HC$1-8)*($G$47:$HB$47>=$HC6))))) | E6: =IF(OR($B6="",$HC6=97),"",SUMPRODUCT(($G$4:$HA$4="ح")*($G6:$HA6=TRUE)*($H6:$HB6<>TRUE)*($G$47:$HA$47>$HC$1-8))) | F6: =IF($B6="","",IF($HE6=0,IF($HC6=97,"-","تمام"),IF($HE6=1,IF(INDEX($G$1:$HB$1,1,17*($HF6-1)+1)="","شهر "&$HF6,INDEX($G$1:$HB$1,1,17*($HF6-1)+1)),IF($HE6=2,"شهرين",$HE6&" شهور")))) | HC6: =97-SUMPRODUCT(MAX(($G$4:$HB$4="ح")*($G6:$HB6=TRUE)*(97-$G$47:$HB$47))) -> 97 | HD6: =SUMPRODUCT(($G$4:$HB$4="ح")*($G6:$HB6=TRUE)*($G$47:$HB$47>$HC$1-8)) -> 0 | HE6: =(COUNTIF($G6:$V6,TRUE)>0)*($W6<>TRUE)+(COUNTIF($X6:$AM6,TRUE)>0)*($AN6<>TRUE)+(COUNTIF($AO6:$BD6,TRUE)>0)*($BE6<>TRUE)+(COUNTIF($BF6:$BU6,TRUE)>0)*($BV6<>TRUE)+(COUNTIF($BW6:$CL6,TRUE)>0)*($CM6<>TRUE)+(COUNTIF($CN6:$DC6,TRUE)>0)*($DD6<>TRUE)+(COUNTIF($DE6:$DT6,TRUE)>0)*($DU6<>TRUE)+(COUNTIF($DV6:$EK6,TRUE)>0)*($EL6<>TRUE)+(COUNTIF($EM6:$FB6,TRUE)>0)*($FC6<>TRUE)+(COUNTIF($FD6:$FS6,TRUE)>0)*($FT6<>TRUE)+(COUNTIF($FU6:$GJ6,TRUE)>0)*($GK6<>TRUE)+(COUNTIF($GL6:$HA6,TRUE)>0)*($HB6<>TRUE) -> 0 | HF6: =IF($HE6=0,0,13-MAX((COUNTIF($G6:$V6,TRUE)>0)*($W6<>TRUE)*12,(COUNTIF($X6:$AM6,TRUE)>0)*($AN6<>TRUE)*11,(COUNTIF($AO6:$BD6,TRUE)>0)*($BE6<>TRUE)*10,(COUNTIF($BF6:$BU6,TRUE)>0)*($BV6<>TRUE)*9,(COUNTIF($BW6:$CL6,TRUE)>0)*($CM6<>TRUE)*8,(COUNTIF($CN6:$DC6,TRUE)>0)*($DD6<>TRUE)*7,(COUNTIF($DE6:$DT6,TRUE)>0)*($DU6<>TRUE)*6,(COUNTIF($DV6:$EK6,TRUE)>0)*($EL6<>TRUE)*5,(COUNTIF($EM6:$FB6,TRUE)>0)*($FC6<>TRUE)*4,(COUNTIF($FD6:$FS6,TRUE)>0)*($FT6<>TRUE)*3,(COUNTIF($FU6:$GJ6,TRUE)>0)*($GK6<>TRUE)*2,(COUNTIF($GL6:$HA6,TRUE)>0)*($HB6<>TRUE)*1)) -> 0
A7: 3 | D7: =IF($B7="","",IF($HC7=97,"-",IF($HD7=0,"متوقف",SUMPRODUCT(($G$4:$HB$4="ح")*($G$20:$HB$20>0)*($G7:$HB7<>TRUE)*($G$47:$HB$47>$HC$1-8)*($G$47:$HB$47>=$HC7))))) | E7: =IF(OR($B7="",$HC7=97),"",SUMPRODUCT(($G$4:$HA$4="ح")*($G7:$HA7=TRUE)*($H7:$HB7<>TRUE)*($G$47:$HA$47>$HC$1-8))) | F7: =IF($B7="","",IF($HE7=0,IF($HC7=97,"-","تمام"),IF($HE7=1,IF(INDEX($G$1:$HB$1,1,17*($HF7-1)+1)="","شهر "&$HF7,INDEX($G$1:$HB$1,1,17*($HF7-1)+1)),IF($HE7=2,"شهرين",$HE7&" شهور")))) | HC7: =97-SUMPRODUCT(MAX(($G$4:$HB$4="ح")*($G7:$HB7=TRUE)*(97-$G$47:$HB$47))) -> 97 | HD7: =SUMPRODUCT(($G$4:$HB$4="ح")*($G7:$HB7=TRUE)*($G$47:$HB$47>$HC$1-8)) -> 0 | HE7: =(COUNTIF($G7:$V7,TRUE)>0)*($W7<>TRUE)+(COUNTIF($X7:$AM7,TRUE)>0)*($AN7<>TRUE)+(COUNTIF($AO7:$BD7,TRUE)>0)*($BE7<>TRUE)+(COUNTIF($BF7:$BU7,TRUE)>0)*($BV7<>TRUE)+(COUNTIF($BW7:$CL7,TRUE)>0)*($CM7<>TRUE)+(COUNTIF($CN7:$DC7,TRUE)>0)*($DD7<>TRUE)+(COUNTIF($DE7:$DT7,TRUE)>0)*($DU7<>TRUE)+(COUNTIF($DV7:$EK7,TRUE)>0)*($EL7<>TRUE)+(COUNTIF($EM7:$FB7,TRUE)>0)*($FC7<>TRUE)+(COUNTIF($FD7:$FS7,TRUE)>0)*($FT7<>TRUE)+(COUNTIF($FU7:$GJ7,TRUE)>0)*($GK7<>TRUE)+(COUNTIF($GL7:$HA7,TRUE)>0)*($HB7<>TRUE) -> 0 | HF7: =IF($HE7=0,0,13-MAX((COUNTIF($G7:$V7,TRUE)>0)*($W7<>TRUE)*12,(COUNTIF($X7:$AM7,TRUE)>0)*($AN7<>TRUE)*11,(COUNTIF($AO7:$BD7,TRUE)>0)*($BE7<>TRUE)*10,(COUNTIF($BF7:$BU7,TRUE)>0)*($BV7<>TRUE)*9,(COUNTIF($BW7:$CL7,TRUE)>0)*($CM7<>TRUE)*8,(COUNTIF($CN7:$DC7,TRUE)>0)*($DD7<>TRUE)*7,(COUNTIF($DE7:$DT7,TRUE)>0)*($DU7<>TRUE)*6,(COUNTIF($DV7:$EK7,TRUE)>0)*($EL7<>TRUE)*5,(COUNTIF($EM7:$FB7,TRUE)>0)*($FC7<>TRUE)*4,(COUNTIF($FD7:$FS7,TRUE)>0)*($FT7<>TRUE)*3,(COUNTIF($FU7:$GJ7,TRUE)>0)*($GK7<>TRUE)*2,(COUNTIF($GL7:$HA7,TRUE)>0)*($HB7<>TRUE)*1)) -> 0
A8: 4 | D8: =IF($B8="","",IF($HC8=97,"-",IF($HD8=0,"متوقف",SUMPRODUCT(($G$4:$HB$4="ح")*($G$20:$HB$20>0)*($G8:$HB8<>TRUE)*($G$47:$HB$47>$HC$1-8)*($G$47:$HB$47>=$HC8))))) | E8: =IF(OR($B8="",$HC8=97),"",SUMPRODUCT(($G$4:$HA$4="ح")*($G8:$HA8=TRUE)*($H8:$HB8<>TRUE)*($G$47:$HA$47>$HC$1-8))) | F8: =IF($B8="","",IF($HE8=0,IF($HC8=97,"-","تمام"),IF($HE8=1,IF(INDEX($G$1:$HB$1,1,17*($HF8-1)+1)="","شهر "&$HF8,INDEX($G$1:$HB$1,1,17*($HF8-1)+1)),IF($HE8=2,"شهرين",$HE8&" شهور")))) | HC8: =97-SUMPRODUCT(MAX(($G$4:$HB$4="ح")*($G8:$HB8=TRUE)*(97-$G$47:$HB$47))) -> 97 | HD8: =SUMPRODUCT(($G$4:$HB$4="ح")*($G8:$HB8=TRUE)*($G$47:$HB$47>$HC$1-8)) -> 0 | HE8: =(COUNTIF($G8:$V8,TRUE)>0)*($W8<>TRUE)+(COUNTIF($X8:$AM8,TRUE)>0)*($AN8<>TRUE)+(COUNTIF($AO8:$BD8,TRUE)>0)*($BE8<>TRUE)+(COUNTIF($BF8:$BU8,TRUE)>0)*($BV8<>TRUE)+(COUNTIF($BW8:$CL8,TRUE)>0)*($CM8<>TRUE)+(COUNTIF($CN8:$DC8,TRUE)>0)*($DD8<>TRUE)+(COUNTIF($DE8:$DT8,TRUE)>0)*($DU8<>TRUE)+(COUNTIF($DV8:$EK8,TRUE)>0)*($EL8<>TRUE)+(COUNTIF($EM8:$FB8,TRUE)>0)*($FC8<>TRUE)+(COUNTIF($FD8:$FS8,TRUE)>0)*($FT8<>TRUE)+(COUNTIF($FU8:$GJ8,TRUE)>0)*($GK8<>TRUE)+(COUNTIF($GL8:$HA8,TRUE)>0)*($HB8<>TRUE) -> 0 | HF8: =IF($HE8=0,0,13-MAX((COUNTIF($G8:$V8,TRUE)>0)*($W8<>TRUE)*12,(COUNTIF($X8:$AM8,TRUE)>0)*($AN8<>TRUE)*11,(COUNTIF($AO8:$BD8,TRUE)>0)*($BE8<>TRUE)*10,(COUNTIF($BF8:$BU8,TRUE)>0)*($BV8<>TRUE)*9,(COUNTIF($BW8:$CL8,TRUE)>0)*($CM8<>TRUE)*8,(COUNTIF($CN8:$DC8,TRUE)>0)*($DD8<>TRUE)*7,(COUNTIF($DE8:$DT8,TRUE)>0)*($DU8<>TRUE)*6,(COUNTIF($DV8:$EK8,TRUE)>0)*($EL8<>TRUE)*5,(COUNTIF($EM8:$FB8,TRUE)>0)*($FC8<>TRUE)*4,(COUNTIF($FD8:$FS8,TRUE)>0)*($FT8<>TRUE)*3,(COUNTIF($FU8:$GJ8,TRUE)>0)*($GK8<>TRUE)*2,(COUNTIF($GL8:$HA8,TRUE)>0)*($HB8<>TRUE)*1)) -> 0
A9: 5 | D9: =IF($B9="","",IF($HC9=97,"-",IF($HD9=0,"متوقف",SUMPRODUCT(($G$4:$HB$4="ح")*($G$20:$HB$20>0)*($G9:$HB9<>TRUE)*($G$47:$HB$47>$HC$1-8)*($G$47:$HB$47>=$HC9))))) | E9: =IF(OR($B9="",$HC9=97),"",SUMPRODUCT(($G$4:$HA$4="ح")*($G9:$HA9=TRUE)*($H9:$HB9<>TRUE)*($G$47:$HA$47>$HC$1-8))) | F9: =IF($B9="","",IF($HE9=0,IF($HC9=97,"-","تمام"),IF($HE9=1,IF(INDEX($G$1:$HB$1,1,17*($HF9-1)+1)="","شهر "&$HF9,INDEX($G$1:$HB$1,1,17*($HF9-1)+1)),IF($HE9=2,"شهرين",$HE9&" شهور")))) | HC9: =97-SUMPRODUCT(MAX(($G$4:$HB$4="ح")*($G9:$HB9=TRUE)*(97-$G$47:$HB$47))) -> 97 | HD9: =SUMPRODUCT(($G$4:$HB$4="ح")*($G9:$HB9=TRUE)*($G$47:$HB$47>$HC$1-8)) -> 0 | HE9: =(COUNTIF($G9:$V9,TRUE)>0)*($W9<>TRUE)+(COUNTIF($X9:$AM9,TRUE)>0)*($AN9<>TRUE)+(COUNTIF($AO9:$BD9,TRUE)>0)*($BE9<>TRUE)+(COUNTIF($BF9:$BU9,TRUE)>0)*($BV9<>TRUE)+(COUNTIF($BW9:$CL9,TRUE)>0)*($CM9<>TRUE)+(COUNTIF($CN9:$DC9,TRUE)>0)*($DD9<>TRUE)+(COUNTIF($DE9:$DT9,TRUE)>0)*($DU9<>TRUE)+(COUNTIF($DV9:$EK9,TRUE)>0)*($EL9<>TRUE)+(COUNTIF($EM9:$FB9,TRUE)>0)*($FC9<>TRUE)+(COUNTIF($FD9:$FS9,TRUE)>0)*($FT9<>TRUE)+(COUNTIF($FU9:$GJ9,TRUE)>0)*($GK9<>TRUE)+(COUNTIF($GL9:$HA9,TRUE)>0)*($HB9<>TRUE) -> 0 | HF9: =IF($HE9=0,0,13-MAX((COUNTIF($G9:$V9,TRUE)>0)*($W9<>TRUE)*12,(COUNTIF($X9:$AM9,TRUE)>0)*($AN9<>TRUE)*11,(COUNTIF($AO9:$BD9,TRUE)>0)*($BE9<>TRUE)*10,(COUNTIF($BF9:$BU9,TRUE)>0)*($BV9<>TRUE)*9,(COUNTIF($BW9:$CL9,TRUE)>0)*($CM9<>TRUE)*8,(COUNTIF($CN9:$DC9,TRUE)>0)*($DD9<>TRUE)*7,(COUNTIF($DE9:$DT9,TRUE)>0)*($DU9<>TRUE)*6,(COUNTIF($DV9:$EK9,TRUE)>0)*($EL9<>TRUE)*5,(COUNTIF($EM9:$FB9,TRUE)>0)*($FC9<>TRUE)*4,(COUNTIF($FD9:$FS9,TRUE)>0)*($FT9<>TRUE)*3,(COUNTIF($FU9:$GJ9,TRUE)>0)*($GK9<>TRUE)*2,(COUNTIF($GL9:$HA9,TRUE)>0)*($HB9<>TRUE)*1)) -> 0
A10: 6 | D10: =IF($B10="","",IF($HC10=97,"-",IF($HD10=0,"متوقف",SUMPRODUCT(($G$4:$HB$4="ح")*($G$20:$HB$20>0)*($G10:$HB10<>TRUE)*($G$47:$HB$47>$HC$1-8)*($G$47:$HB$47>=$HC10))))) | E10: =IF(OR($B10="",$HC10=97),"",SUMPRODUCT(($G$4:$HA$4="ح")*($G10:$HA10=TRUE)*($H10:$HB10<>TRUE)*($G$47:$HA$47>$HC$1-8))) | F10: =IF($B10="","",IF($HE10=0,IF($HC10=97,"-","تمام"),IF($HE10=1,IF(INDEX($G$1:$HB$1,1,17*($HF10-1)+1)="","شهر "&$HF10,INDEX($G$1:$HB$1,1,17*($HF10-1)+1)),IF($HE10=2,"شهرين",$HE10&" شهور")))) | HC10: =97-SUMPRODUCT(MAX(($G$4:$HB$4="ح")*($G10:$HB10=TRUE)*(97-$G$47:$HB$47))) -> 97 | HD10: =SUMPRODUCT(($G$4:$HB$4="ح")*($G10:$HB10=TRUE)*($G$47:$HB$47>$HC$1-8)) -> 0 | HE10: =(COUNTIF($G10:$V10,TRUE)>0)*($W10<>TRUE)+(COUNTIF($X10:$AM10,TRUE)>0)*($AN10<>TRUE)+(COUNTIF($AO10:$BD10,TRUE)>0)*($BE10<>TRUE)+(COUNTIF($BF10:$BU10,TRUE)>0)*($BV10<>TRUE)+(COUNTIF($BW10:$CL10,TRUE)>0)*($CM10<>TRUE)+(COUNTIF($CN10:$DC10,TRUE)>0)*($DD10<>TRUE)+(COUNTIF($DE10:$DT10,TRUE)>0)*($DU10<>TRUE)+(COUNTIF($DV10:$EK10,TRUE)>0)*($EL10<>TRUE)+(COUNTIF($EM10:$FB10,TRUE)>0)*($FC10<>TRUE)+(COUNTIF($FD10:$FS10,TRUE)>0)*($FT10<>TRUE)+(COUNTIF($FU10:$GJ10,TRUE)>0)*($GK10<>TRUE)+(COUNTIF($GL10:$HA10,TRUE)>0)*($HB10<>TRUE) -> 0 | HF10: =IF($HE10=0,0,13-MAX((COUNTIF($G10:$V10,TRUE)>0)*($W10<>TRUE)*12,(COUNTIF($X10:$AM10,TRUE)>0)*($AN10<>TRUE)*11,(COUNTIF($AO10:$BD10,TRUE)>0)*($BE10<>TRUE)*10,(COUNTIF($BF10:$BU10,TRUE)>0)*($BV10<>TRUE)*9,(COUNTIF($BW10:$CL10,TRUE)>0)*($CM10<>TRUE)*8,(COUNTIF($CN10:$DC10,TRUE)>0)*($DD10<>TRUE)*7,(COUNTIF($DE10:$DT10,TRUE)>0)*($DU10<>TRUE)*6,(COUNTIF($DV10:$EK10,TRUE)>0)*($EL10<>TRUE)*5,(COUNTIF($EM10:$FB10,TRUE)>0)*($FC10<>TRUE)*4,(COUNTIF($FD10:$FS10,TRUE)>0)*($FT10<>TRUE)*3,(COUNTIF($FU10:$GJ10,TRUE)>0)*($GK10<>TRUE)*2,(COUNTIF($GL10:$HA10,TRUE)>0)*($HB10<>TRUE)*1)) -> 0
A11: 7 | D11: =IF($B11="","",IF($HC11=97,"-",IF($HD11=0,"متوقف",SUMPRODUCT(($G$4:$HB$4="ح")*($G$20:$HB$20>0)*($G11:$HB11<>TRUE)*($G$47:$HB$47>$HC$1-8)*($G$47:$HB$47>=$HC11))))) | E11: =IF(OR($B11="",$HC11=97),"",SUMPRODUCT(($G$4:$HA$4="ح")*($G11:$HA11=TRUE)*($H11:$HB11<>TRUE)*($G$47:$HA$47>$HC$1-8))) | F11: =IF($B11="","",IF($HE11=0,IF($HC11=97,"-","تمام"),IF($HE11=1,IF(INDEX($G$1:$HB$1,1,17*($HF11-1)+1)="","شهر "&$HF11,INDEX($G$1:$HB$1,1,17*($HF11-1)+1)),IF($HE11=2,"شهرين",$HE11&" شهور")))) | HC11: =97-SUMPRODUCT(MAX(($G$4:$HB$4="ح")*($G11:$HB11=TRUE)*(97-$G$47:$HB$47))) -> 97 | HD11: =SUMPRODUCT(($G$4:$HB$4="ح")*($G11:$HB11=TRUE)*($G$47:$HB$47>$HC$1-8)) -> 0 | HE11: =(COUNTIF($G11:$V11,TRUE)>0)*($W11<>TRUE)+(COUNTIF($X11:$AM11,TRUE)>0)*($AN11<>TRUE)+(COUNTIF($AO11:$BD11,TRUE)>0)*($BE11<>TRUE)+(COUNTIF($BF11:$BU11,TRUE)>0)*($BV11<>TRUE)+(COUNTIF($BW11:$CL11,TRUE)>0)*($CM11<>TRUE)+(COUNTIF($CN11:$DC11,TRUE)>0)*($DD11<>TRUE)+(COUNTIF($DE11:$DT11,TRUE)>0)*($DU11<>TRUE)+(COUNTIF($DV11:$EK11,TRUE)>0)*($EL11<>TRUE)+(COUNTIF($EM11:$FB11,TRUE)>0)*($FC11<>TRUE)+(COUNTIF($FD11:$FS11,TRUE)>0)*($FT11<>TRUE)+(COUNTIF($FU11:$GJ11,TRUE)>0)*($GK11<>TRUE)+(COUNTIF($GL11:$HA11,TRUE)>0)*($HB11<>TRUE) -> 0 | HF11: =IF($HE11=0,0,13-MAX((COUNTIF($G11:$V11,TRUE)>0)*($W11<>TRUE)*12,(COUNTIF($X11:$AM11,TRUE)>0)*($AN11<>TRUE)*11,(COUNTIF($AO11:$BD11,TRUE)>0)*($BE11<>TRUE)*10,(COUNTIF($BF11:$BU11,TRUE)>0)*($BV11<>TRUE)*9,(COUNTIF($BW11:$CL11,TRUE)>0)*($CM11<>TRUE)*8,(COUNTIF($CN11:$DC11,TRUE)>0)*($DD11<>TRUE)*7,(COUNTIF($DE11:$DT11,TRUE)>0)*($DU11<>TRUE)*6,(COUNTIF($DV11:$EK11,TRUE)>0)*($EL11<>TRUE)*5,(COUNTIF($EM11:$FB11,TRUE)>0)*($FC11<>TRUE)*4,(COUNTIF($FD11:$FS11,TRUE)>0)*($FT11<>TRUE)*3,(COUNTIF($FU11:$GJ11,TRUE)>0)*($GK11<>TRUE)*2,(COUNTIF($GL11:$HA11,TRUE)>0)*($HB11<>TRUE)*1)) -> 0
A12: 8 | D12: =IF($B12="","",IF($HC12=97,"-",IF($HD12=0,"متوقف",SUMPRODUCT(($G$4:$HB$4="ح")*($G$20:$HB$20>0)*($G12:$HB12<>TRUE)*($G$47:$HB$47>$HC$1-8)*($G$47:$HB$47>=$HC12))))) | E12: =IF(OR($B12="",$HC12=97),"",SUMPRODUCT(($G$4:$HA$4="ح")*($G12:$HA12=TRUE)*($H12:$HB12<>TRUE)*($G$47:$HA$47>$HC$1-8))) | F12: =IF($B12="","",IF($HE12=0,IF($HC12=97,"-","تمام"),IF($HE12=1,IF(INDEX($G$1:$HB$1,1,17*($HF12-1)+1)="","شهر "&$HF12,INDEX($G$1:$HB$1,1,17*($HF12-1)+1)),IF($HE12=2,"شهرين",$HE12&" شهور")))) | HC12: =97-SUMPRODUCT(MAX(($G$4:$HB$4="ح")*($G12:$HB12=TRUE)*(97-$G$47:$HB$47))) -> 97 | HD12: =SUMPRODUCT(($G$4:$HB$4="ح")*($G12:$HB12=TRUE)*($G$47:$HB$47>$HC$1-8)) -> 0 | HE12: =(COUNTIF($G12:$V12,TRUE)>0)*($W12<>TRUE)+(COUNTIF($X12:$AM12,TRUE)>0)*($AN12<>TRUE)+(COUNTIF($AO12:$BD12,TRUE)>0)*($BE12<>TRUE)+(COUNTIF($BF12:$BU12,TRUE)>0)*($BV12<>TRUE)+(COUNTIF($BW12:$CL12,TRUE)>0)*($CM12<>TRUE)+(COUNTIF($CN12:$DC12,TRUE)>0)*($DD12<>TRUE)+(COUNTIF($DE12:$DT12,TRUE)>0)*($DU12<>TRUE)+(COUNTIF($DV12:$EK12,TRUE)>0)*($EL12<>TRUE)+(COUNTIF($EM12:$FB12,TRUE)>0)*($FC12<>TRUE)+(COUNTIF($FD12:$FS12,TRUE)>0)*($FT12<>TRUE)+(COUNTIF($FU12:$GJ12,TRUE)>0)*($GK12<>TRUE)+(COUNTIF($GL12:$HA12,TRUE)>0)*($HB12<>TRUE) -> 0 | HF12: =IF($HE12=0,0,13-MAX((COUNTIF($G12:$V12,TRUE)>0)*($W12<>TRUE)*12,(COUNTIF($X12:$AM12,TRUE)>0)*($AN12<>TRUE)*11,(COUNTIF($AO12:$BD12,TRUE)>0)*($BE12<>TRUE)*10,(COUNTIF($BF12:$BU12,TRUE)>0)*($BV12<>TRUE)*9,(COUNTIF($BW12:$CL12,TRUE)>0)*($CM12<>TRUE)*8,(COUNTIF($CN12:$DC12,TRUE)>0)*($DD12<>TRUE)*7,(COUNTIF($DE12:$DT12,TRUE)>0)*($DU12<>TRUE)*6,(COUNTIF($DV12:$EK12,TRUE)>0)*($EL12<>TRUE)*5,(COUNTIF($EM12:$FB12,TRUE)>0)*($FC12<>TRUE)*4,(COUNTIF($FD12:$FS12,TRUE)>0)*($FT12<>TRUE)*3,(COUNTIF($FU12:$GJ12,TRUE)>0)*($GK12<>TRUE)*2,(COUNTIF($GL12:$HA12,TRUE)>0)*($HB12<>TRUE)*1)) -> 0
A13: 9 | D13: =IF($B13="","",IF($HC13=97,"-",IF($HD13=0,"متوقف",SUMPRODUCT(($G$4:$HB$4="ح")*($G$20:$HB$20>0)*($G13:$HB13<>TRUE)*($G$47:$HB$47>$HC$1-8)*($G$47:$HB$47>=$HC13))))) | E13: =IF(OR($B13="",$HC13=97),"",SUMPRODUCT(($G$4:$HA$4="ح")*($G13:$HA13=TRUE)*($H13:$HB13<>TRUE)*($G$47:$HA$47>$HC$1-8))) | F13: =IF($B13="","",IF($HE13=0,IF($HC13=97,"-","تمام"),IF($HE13=1,IF(INDEX($G$1:$HB$1,1,17*($HF13-1)+1)="","شهر "&$HF13,INDEX($G$1:$HB$1,1,17*($HF13-1)+1)),IF($HE13=2,"شهرين",$HE13&" شهور")))) | HC13: =97-SUMPRODUCT(MAX(($G$4:$HB$4="ح")*($G13:$HB13=TRUE)*(97-$G$47:$HB$47))) -> 97 | HD13: =SUMPRODUCT(($G$4:$HB$4="ح")*($G13:$HB13=TRUE)*($G$47:$HB$47>$HC$1-8)) -> 0 | HE13: =(COUNTIF($G13:$V13,TRUE)>0)*($W13<>TRUE)+(COUNTIF($X13:$AM13,TRUE)>0)*($AN13<>TRUE)+(COUNTIF($AO13:$BD13,TRUE)>0)*($BE13<>TRUE)+(COUNTIF($BF13:$BU13,TRUE)>0)*($BV13<>TRUE)+(COUNTIF($BW13:$CL13,TRUE)>0)*($CM13<>TRUE)+(COUNTIF($CN13:$DC13,TRUE)>0)*($DD13<>TRUE)+(COUNTIF($DE13:$DT13,TRUE)>0)*($DU13<>TRUE)+(COUNTIF($DV13:$EK13,TRUE)>0)*($EL13<>TRUE)+(COUNTIF($EM13:$FB13,TRUE)>0)*($FC13<>TRUE)+(COUNTIF($FD13:$FS13,TRUE)>0)*($FT13<>TRUE)+(COUNTIF($FU13:$GJ13,TRUE)>0)*($GK13<>TRUE)+(COUNTIF($GL13:$HA13,TRUE)>0)*($HB13<>TRUE) -> 0 | HF13: =IF($HE13=0,0,13-MAX((COUNTIF($G13:$V13,TRUE)>0)*($W13<>TRUE)*12,(COUNTIF($X13:$AM13,TRUE)>0)*($AN13<>TRUE)*11,(COUNTIF($AO13:$BD13,TRUE)>0)*($BE13<>TRUE)*10,(COUNTIF($BF13:$BU13,TRUE)>0)*($BV13<>TRUE)*9,(COUNTIF($BW13:$CL13,TRUE)>0)*($CM13<>TRUE)*8,(COUNTIF($CN13:$DC13,TRUE)>0)*($DD13<>TRUE)*7,(COUNTIF($DE13:$DT13,TRUE)>0)*($DU13<>TRUE)*6,(COUNTIF($DV13:$EK13,TRUE)>0)*($EL13<>TRUE)*5,(COUNTIF($EM13:$FB13,TRUE)>0)*($FC13<>TRUE)*4,(COUNTIF($FD13:$FS13,TRUE)>0)*($FT13<>TRUE)*3,(COUNTIF($FU13:$GJ13,TRUE)>0)*($GK13<>TRUE)*2,(COUNTIF($GL13:$HA13,TRUE)>0)*($HB13<>TRUE)*1)) -> 0
A14: 10 | D14: =IF($B14="","",IF($HC14=97,"-",IF($HD14=0,"متوقف",SUMPRODUCT(($G$4:$HB$4="ح")*($G$20:$HB$20>0)*($G14:$HB14<>TRUE)*($G$47:$HB$47>$HC$1-8)*($G$47:$HB$47>=$HC14))))) | E14: =IF(OR($B14="",$HC14=97),"",SUMPRODUCT(($G$4:$HA$4="ح")*($G14:$HA14=TRUE)*($H14:$HB14<>TRUE)*($G$47:$HA$47>$HC$1-8))) | F14: =IF($B14="","",IF($HE14=0,IF($HC14=97,"-","تمام"),IF($HE14=1,IF(INDEX($G$1:$HB$1,1,17*($HF14-1)+1)="","شهر "&$HF14,INDEX($G$1:$HB$1,1,17*($HF14-1)+1)),IF($HE14=2,"شهرين",$HE14&" شهور")))) | HC14: =97-SUMPRODUCT(MAX(($G$4:$HB$4="ح")*($G14:$HB14=TRUE)*(97-$G$47:$HB$47))) -> 97 | HD14: =SUMPRODUCT(($G$4:$HB$4="ح")*($G14:$HB14=TRUE)*($G$47:$HB$47>$HC$1-8)) -> 0 | HE14: =(COUNTIF($G14:$V14,TRUE)>0)*($W14<>TRUE)+(COUNTIF($X14:$AM14,TRUE)>0)*($AN14<>TRUE)+(COUNTIF($AO14:$BD14,TRUE)>0)*($BE14<>TRUE)+(COUNTIF($BF14:$BU14,TRUE)>0)*($BV14<>TRUE)+(COUNTIF($BW14:$CL14,TRUE)>0)*($CM14<>TRUE)+(COUNTIF($CN14:$DC14,TRUE)>0)*($DD14<>TRUE)+(COUNTIF($DE14:$DT14,TRUE)>0)*($DU14<>TRUE)+(COUNTIF($DV14:$EK14,TRUE)>0)*($EL14<>TRUE)+(COUNTIF($EM14:$FB14,TRUE)>0)*($FC14<>TRUE)+(COUNTIF($FD14:$FS14,TRUE)>0)*($FT14<>TRUE)+(COUNTIF($FU14:$GJ14,TRUE)>0)*($GK14<>TRUE)+(COUNTIF($GL14:$HA14,TRUE)>0)*($HB14<>TRUE) -> 0 | HF14: =IF($HE14=0,0,13-MAX((COUNTIF($G14:$V14,TRUE)>0)*($W14<>TRUE)*12,(COUNTIF($X14:$AM14,TRUE)>0)*($AN14<>TRUE)*11,(COUNTIF($AO14:$BD14,TRUE)>0)*($BE14<>TRUE)*10,(COUNTIF($BF14:$BU14,TRUE)>0)*($BV14<>TRUE)*9,(COUNTIF($BW14:$CL14,TRUE)>0)*($CM14<>TRUE)*8,(COUNTIF($CN14:$DC14,TRUE)>0)*($DD14<>TRUE)*7,(COUNTIF($DE14:$DT14,TRUE)>0)*($DU14<>TRUE)*6,(COUNTIF($DV14:$EK14,TRUE)>0)*($EL14<>TRUE)*5,(COUNTIF($EM14:$FB14,TRUE)>0)*($FC14<>TRUE)*4,(COUNTIF($FD14:$FS14,TRUE)>0)*($FT14<>TRUE)*3,(COUNTIF($FU14:$GJ14,TRUE)>0)*($GK14<>TRUE)*2,(COUNTIF($GL14:$HA14,TRUE)>0)*($HB14<>TRUE)*1)) -> 0
A15: 11 | D15: =IF($B15="","",IF($HC15=97,"-",IF($HD15=0,"متوقف",SUMPRODUCT(($G$4:$HB$4="ح")*($G$20:$HB$20>0)*($G15:$HB15<>TRUE)*($G$47:$HB$47>$HC$1-8)*($G$47:$HB$47>=$HC15))))) | E15: =IF(OR($B15="",$HC15=97),"",SUMPRODUCT(($G$4:$HA$4="ح")*($G15:$HA15=TRUE)*($H15:$HB15<>TRUE)*($G$47:$HA$47>$HC$1-8))) | F15: =IF($B15="","",IF($HE15=0,IF($HC15=97,"-","تمام"),IF($HE15=1,IF(INDEX($G$1:$HB$1,1,17*($HF15-1)+1)="","شهر "&$HF15,INDEX($G$1:$HB$1,1,17*($HF15-1)+1)),IF($HE15=2,"شهرين",$HE15&" شهور")))) | HC15: =97-SUMPRODUCT(MAX(($G$4:$HB$4="ح")*($G15:$HB15=TRUE)*(97-$G$47:$HB$47))) -> 97 | HD15: =SUMPRODUCT(($G$4:$HB$4="ح")*($G15:$HB15=TRUE)*($G$47:$HB$47>$HC$1-8)) -> 0 | HE15: =(COUNTIF($G15:$V15,TRUE)>0)*($W15<>TRUE)+(COUNTIF($X15:$AM15,TRUE)>0)*($AN15<>TRUE)+(COUNTIF($AO15:$BD15,TRUE)>0)*($BE15<>TRUE)+(COUNTIF($BF15:$BU15,TRUE)>0)*($BV15<>TRUE)+(COUNTIF($BW15:$CL15,TRUE)>0)*($CM15<>TRUE)+(COUNTIF($CN15:$DC15,TRUE)>0)*($DD15<>TRUE)+(COUNTIF($DE15:$DT15,TRUE)>0)*($DU15<>TRUE)+(COUNTIF($DV15:$EK15,TRUE)>0)*($EL15<>TRUE)+(COUNTIF($EM15:$FB15,TRUE)>0)*($FC15<>TRUE)+(COUNTIF($FD15:$FS15,TRUE)>0)*($FT15<>TRUE)+(COUNTIF($FU15:$GJ15,TRUE)>0)*($GK15<>TRUE)+(COUNTIF($GL15:$HA15,TRUE)>0)*($HB15<>TRUE) -> 0 | HF15: =IF($HE15=0,0,13-MAX((COUNTIF($G15:$V15,TRUE)>0)*($W15<>TRUE)*12,(COUNTIF($X15:$AM15,TRUE)>0)*($AN15<>TRUE)*11,(COUNTIF($AO15:$BD15,TRUE)>0)*($BE15<>TRUE)*10,(COUNTIF($BF15:$BU15,TRUE)>0)*($BV15<>TRUE)*9,(COUNTIF($BW15:$CL15,TRUE)>0)*($CM15<>TRUE)*8,(COUNTIF($CN15:$DC15,TRUE)>0)*($DD15<>TRUE)*7,(COUNTIF($DE15:$DT15,TRUE)>0)*($DU15<>TRUE)*6,(COUNTIF($DV15:$EK15,TRUE)>0)*($EL15<>TRUE)*5,(COUNTIF($EM15:$FB15,TRUE)>0)*($FC15<>TRUE)*4,(COUNTIF($FD15:$FS15,TRUE)>0)*($FT15<>TRUE)*3,(COUNTIF($FU15:$GJ15,TRUE)>0)*($GK15<>TRUE)*2,(COUNTIF($GL15:$HA15,TRUE)>0)*($HB15<>TRUE)*1)) -> 0
A16: 12 | D16: =IF($B16="","",IF($HC16=97,"-",IF($HD16=0,"متوقف",SUMPRODUCT(($G$4:$HB$4="ح")*($G$20:$HB$20>0)*($G16:$HB16<>TRUE)*($G$47:$HB$47>$HC$1-8)*($G$47:$HB$47>=$HC16))))) | E16: =IF(OR($B16="",$HC16=97),"",SUMPRODUCT(($G$4:$HA$4="ح")*($G16:$HA16=TRUE)*($H16:$HB16<>TRUE)*($G$47:$HA$47>$HC$1-8))) | F16: =IF($B16="","",IF($HE16=0,IF($HC16=97,"-","تمام"),IF($HE16=1,IF(INDEX($G$1:$HB$1,1,17*($HF16-1)+1)="","شهر "&$HF16,INDEX($G$1:$HB$1,1,17*($HF16-1)+1)),IF($HE16=2,"شهرين",$HE16&" شهور")))) | HC16: =97-SUMPRODUCT(MAX(($G$4:$HB$4="ح")*($G16:$HB16=TRUE)*(97-$G$47:$HB$47))) -> 97 | HD16: =SUMPRODUCT(($G$4:$HB$4="ح")*($G16:$HB16=TRUE)*($G$47:$HB$47>$HC$1-8)) -> 0 | HE16: =(COUNTIF($G16:$V16,TRUE)>0)*($W16<>TRUE)+(COUNTIF($X16:$AM16,TRUE)>0)*($AN16<>TRUE)+(COUNTIF($AO16:$BD16,TRUE)>0)*($BE16<>TRUE)+(COUNTIF($BF16:$BU16,TRUE)>0)*($BV16<>TRUE)+(COUNTIF($BW16:$CL16,TRUE)>0)*($CM16<>TRUE)+(COUNTIF($CN16:$DC16,TRUE)>0)*($DD16<>TRUE)+(COUNTIF($DE16:$DT16,TRUE)>0)*($DU16<>TRUE)+(COUNTIF($DV16:$EK16,TRUE)>0)*($EL16<>TRUE)+(COUNTIF($EM16:$FB16,TRUE)>0)*($FC16<>TRUE)+(COUNTIF($FD16:$FS16,TRUE)>0)*($FT16<>TRUE)+(COUNTIF($FU16:$GJ16,TRUE)>0)*($GK16<>TRUE)+(COUNTIF($GL16:$HA16,TRUE)>0)*($HB16<>TRUE) -> 0 | HF16: =IF($HE16=0,0,13-MAX((COUNTIF($G16:$V16,TRUE)>0)*($W16<>TRUE)*12,(COUNTIF($X16:$AM16,TRUE)>0)*($AN16<>TRUE)*11,(COUNTIF($AO16:$BD16,TRUE)>0)*($BE16<>TRUE)*10,(COUNTIF($BF16:$BU16,TRUE)>0)*($BV16<>TRUE)*9,(COUNTIF($BW16:$CL16,TRUE)>0)*($CM16<>TRUE)*8,(COUNTIF($CN16:$DC16,TRUE)>0)*($DD16<>TRUE)*7,(COUNTIF($DE16:$DT16,TRUE)>0)*($DU16<>TRUE)*6,(COUNTIF($DV16:$EK16,TRUE)>0)*($EL16<>TRUE)*5,(COUNTIF($EM16:$FB16,TRUE)>0)*($FC16<>TRUE)*4,(COUNTIF($FD16:$FS16,TRUE)>0)*($FT16<>TRUE)*3,(COUNTIF($FU16:$GJ16,TRUE)>0)*($GK16<>TRUE)*2,(COUNTIF($GL16:$HA16,TRUE)>0)*($HB16<>TRUE)*1)) -> 0
A17: 13 | D17: =IF($B17="","",IF($HC17=97,"-",IF($HD17=0,"متوقف",SUMPRODUCT(($G$4:$HB$4="ح")*($G$20:$HB$20>0)*($G17:$HB17<>TRUE)*($G$47:$HB$47>$HC$1-8)*($G$47:$HB$47>=$HC17))))) | E17: =IF(OR($B17="",$HC17=97),"",SUMPRODUCT(($G$4:$HA$4="ح")*($G17:$HA17=TRUE)*($H17:$HB17<>TRUE)*($G$47:$HA$47>$HC$1-8))) | F17: =IF($B17="","",IF($HE17=0,IF($HC17=97,"-","تمام"),IF($HE17=1,IF(INDEX($G$1:$HB$1,1,17*($HF17-1)+1)="","شهر "&$HF17,INDEX($G$1:$HB$1,1,17*($HF17-1)+1)),IF($HE17=2,"شهرين",$HE17&" شهور")))) | HC17: =97-SUMPRODUCT(MAX(($G$4:$HB$4="ح")*($G17:$HB17=TRUE)*(97-$G$47:$HB$47))) -> 97 | HD17: =SUMPRODUCT(($G$4:$HB$4="ح")*($G17:$HB17=TRUE)*($G$47:$HB$47>$HC$1-8)) -> 0 | HE17: =(COUNTIF($G17:$V17,TRUE)>0)*($W17<>TRUE)+(COUNTIF($X17:$AM17,TRUE)>0)*($AN17<>TRUE)+(COUNTIF($AO17:$BD17,TRUE)>0)*($BE17<>TRUE)+(COUNTIF($BF17:$BU17,TRUE)>0)*($BV17<>TRUE)+(COUNTIF($BW17:$CL17,TRUE)>0)*($CM17<>TRUE)+(COUNTIF($CN17:$DC17,TRUE)>0)*($DD17<>TRUE)+(COUNTIF($DE17:$DT17,TRUE)>0)*($DU17<>TRUE)+(COUNTIF($DV17:$EK17,TRUE)>0)*($EL17<>TRUE)+(COUNTIF($EM17:$FB17,TRUE)>0)*($FC17<>TRUE)+(COUNTIF($FD17:$FS17,TRUE)>0)*($FT17<>TRUE)+(COUNTIF($FU17:$GJ17,TRUE)>0)*($GK17<>TRUE)+(COUNTIF($GL17:$HA17,TRUE)>0)*($HB17<>TRUE) -> 0 | HF17: =IF($HE17=0,0,13-MAX((COUNTIF($G17:$V17,TRUE)>0)*($W17<>TRUE)*12,(COUNTIF($X17:$AM17,TRUE)>0)*($AN17<>TRUE)*11,(COUNTIF($AO17:$BD17,TRUE)>0)*($BE17<>TRUE)*10,(COUNTIF($BF17:$BU17,TRUE)>0)*($BV17<>TRUE)*9,(COUNTIF($BW17:$CL17,TRUE)>0)*($CM17<>TRUE)*8,(COUNTIF($CN17:$DC17,TRUE)>0)*($DD17<>TRUE)*7,(COUNTIF($DE17:$DT17,TRUE)>0)*($DU17<>TRUE)*6,(COUNTIF($DV17:$EK17,TRUE)>0)*($EL17<>TRUE)*5,(COUNTIF($EM17:$FB17,TRUE)>0)*($FC17<>TRUE)*4,(COUNTIF($FD17:$FS17,TRUE)>0)*($FT17<>TRUE)*3,(COUNTIF($FU17:$GJ17,TRUE)>0)*($GK17<>TRUE)*2,(COUNTIF($GL17:$HA17,TRUE)>0)*($HB17<>TRUE)*1)) -> 0
... A19: 15 | D19: =IF($B19="","",IF($HC19=97,"-",IF($HD19=0,"متوقف",SUMPRODUCT(($G$4:$HB$4="ح")*($G$20:$HB$20>0)*($G19:$HB19<>TRUE)*($G$47:$HB$47>$HC$1-8)*($G$47:$HB$47>=$HC19))))) | E19: =IF(OR($B19="",$HC19=97),"",SUMPRODUCT(($G$4:$HA$4="ح")*($G19:$HA19=TRUE)*($H19:$HB19<>TRUE)*($G$47:$HA$47>$HC$1-8))) | F19: =IF($B19="","",IF($HE19=0,IF($HC19=97,"-","تمام"),IF($HE19=1,IF(INDEX($G$1:$HB$1,1,17*($HF19-1)+1)="","شهر "&$HF19,INDEX($G$1:$HB$1,1,17*($HF19-1)+1)),IF($HE19=2,"شهرين",$HE19&" شهور")))) | HC19: =97-SUMPRODUCT(MAX(($G$4:$HB$4="ح")*($G19:$HB19=TRUE)*(97-$G$47:$HB$47))) -> 97 | HD19: =SUMPRODUCT(($G$4:$HB$4="ح")*($G19:$HB19=TRUE)*($G$47:$HB$47>$HC$1-8)) -> 0 | HE19: =(COUNTIF($G19:$V19,TRUE)>0)*($W19<>TRUE)+(COUNTIF($X19:$AM19,TRUE)>0)*($AN19<>TRUE)+(COUNTIF($AO19:$BD19,TRUE)>0)*($BE19<>TRUE)+(COUNTIF($BF19:$BU19,TRUE)>0)*($BV19<>TRUE)+(COUNTIF($BW19:$CL19,TRUE)>0)*($CM19<>TRUE)+(COUNTIF($CN19:$DC19,TRUE)>0)*($DD19<>TRUE)+(COUNTIF($DE19:$DT19,TRUE)>0)*($DU19<>TRUE)+(COUNTIF($DV19:$EK19,TRUE)>0)*($EL19<>TRUE)+(COUNTIF($EM19:$FB19,TRUE)>0)*($FC19<>TRUE)+(COUNTIF($FD19:$FS19,TRUE)>0)*($FT19<>TRUE)+(COUNTIF($FU19:$GJ19,TRUE)>0)*($GK19<>TRUE)+(COUNTIF($GL19:$HA19,TRUE)>0)*($HB19<>TRUE) -> 0 | HF19: =IF($HE19=0,0,13-MAX((COUNTIF($G19:$V19,TRUE)>0)*($W19<>TRUE)*12,(COUNTIF($X19:$AM19,TRUE)>0)*($AN19<>TRUE)*11,(COUNTIF($AO19:$BD19,TRUE)>0)*($BE19<>TRUE)*10,(COUNTIF($BF19:$BU19,TRUE)>0)*($BV19<>TRUE)*9,(COUNTIF($BW19:$CL19,TRUE)>0)*($CM19<>TRUE)*8,(COUNTIF($CN19:$DC19,TRUE)>0)*($DD19<>TRUE)*7,(COUNTIF($DE19:$DT19,TRUE)>0)*($DU19<>TRUE)*6,(COUNTIF($DV19:$EK19,TRUE)>0)*($EL19<>TRUE)*5,(COUNTIF($EM19:$FB19,TRUE)>0)*($FC19<>TRUE)*4,(COUNTIF($FD19:$FS19,TRUE)>0)*($FT19<>TRUE)*3,(COUNTIF($FU19:$GJ19,TRUE)>0)*($GK19<>TRUE)*2,(COUNTIF($GL19:$HA19,TRUE)>0)*($HB19<>TRUE)*1)) -> 0
A20: العدد | G20: =COUNTIF(G5:G19,TRUE) -> 0 | H20: =COUNTIF(H5:H19,TRUE) -> 0 | I20: =COUNTIF(I5:I19,TRUE) -> 0 | J20: =COUNTIF(J5:J19,TRUE) -> 0 | K20: =COUNTIF(K5:K19,TRUE) -> 0 | L20: =COUNTIF(L5:L19,TRUE) -> 0 | M20: =COUNTIF(M5:M19,TRUE) -> 0 | N20: =COUNTIF(N5:N19,TRUE) -> 0 | ... HB20: =COUNTIF(HB5:HB19,TRUE) -> 0
A22: الحصة الجاية: هنعمل إيه؟ | C22: ميعادها حسب صفحة المواعيد
C23: =IF($HF$4="","مفيش ميعاد للمجموعة دي في صفحة المواعيد",$HF$4) -> بكرة 3/10 – 5:00 م
A24: ميعاد مختلف؟ (اختياري) | C24: لو الحصة اتأجلت أو في حصة إضافية، اكتبي ميعادها في الخانة البيضا
A27: الدرجات · نوع الامتحان | C27: النسبة والترتيب على: | F27: الكل | W27: ملاحظات (سبب الغياب) | AN27: ملاحظات (سبب الغياب) | BE27: ملاحظات (سبب الغياب) | BV27: ملاحظات (سبب الغياب) | CM27: ملاحظات (سبب الغياب) | DD27: ملاحظات (سبب الغياب) | DU27: ملاحظات (سبب الغياب) | EL27: ملاحظات (سبب الغياب) | FC27: ملاحظات (سبب الغياب) | FT27: ملاحظات (سبب الغياب) | GK27: ملاحظات (سبب الغياب) | HB27: ملاحظات (سبب الغياب)
A28: الدرجة النهائية (من كام) | C28: الدرجة ما بتتحسبش من غير نهائية
A29: م | B29: الاسم | C29: المجموع | D29: % | E29: الترتيب | F29: التقدير | G29: كويز | H29: امتحان | I29: كويز | J29: امتحان | K29: كويز | L29: امتحان | M29: كويز | N29: امتحان | O29: كويز | P29: امتحان | Q29: كويز | R29: امتحان | S29: كويز | T29: امتحان | U29: كويز | V29: امتحان | W29: ملاحظات | X29: كويز | Y29: امتحان | Z29: كويز | AA29: امتحان | AB29: كويز | AC29: امتحان | AD29: كويز | AE29: امتحان | AF29: كويز | AG29: امتحان | AH29: كويز | AI29: امتحان | AJ29: كويز | AK29: امتحان | AL29: كويز | AM29: امتحان | AN29: ملاحظات | AO29: كويز | AP29: امتحان | AQ29: كويز | AR29: امتحان | AS29: كويز | AT29: امتحان | AU29: كويز | AV29: امتحان | AW29: كويز | AX29: امتحان | AY29: كويز | AZ29: امتحان | BA29: كويز | BB29: امتحان | BC29: كويز | BD29: امتحان | BE29: ملاحظات | BF29: كويز | BG29: امتحان | BH29: كويز | BI29: امتحان | BJ29: كويز | BK29: امتحان | BL29: كويز | BM29: امتحان | BN29: كويز | BO29: امتحان | BP29: كويز | BQ29: امتحان | BR29: كويز | BS29: امتحان | BT29: كويز | BU29: امتحان | BV29: ملاحظات | BW29: كويز | BX29: امتحان | BY29: كويز | BZ29: امتحان | CA29: كويز | CB29: امتحان | CC29: كويز | CD29: امتحان | CE29: كويز | CF29: امتحان | CG29: كويز | CH29: امتحان | CI29: كويز | CJ29: امتحان | CK29: كويز | CL29: امتحان | CM29: ملاحظات | CN29: كويز | CO29: امتحان | CP29: كويز | CQ29: امتحان | CR29: كويز | CS29: امتحان | CT29: كويز | CU29: امتحان | CV29: كويز | CW29: امتحان | CX29: كويز | CY29: امتحان | CZ29: كويز | DA29: امتحان | DB29: كويز | DC29: امتحان | DD29: ملاحظات | DE29: كويز | DF29: امتحان | DG29: كويز | DH29: امتحان | DI29: كويز | DJ29: امتحان | DK29: كويز | DL29: امتحان | DM29: كويز | DN29: امتحان | DO29: كويز | DP29: امتحان | DQ29: كويز | DR29: امتحان | DS29: كويز | DT29: امتحان | DU29: ملاحظات | DV29: كويز | DW29: امتحان | DX29: كويز | DY29: امتحان | DZ29: كويز | EA29: امتحان | EB29: كويز | EC29: امتحان | ED29: كويز | EE29: امتحان | EF29: كويز | EG29: امتحان | EH29: كويز | EI29: امتحان | EJ29: كويز | EK29: امتحان | EL29: ملاحظات | EM29: كويز | EN29: امتحان | EO29: كويز | EP29: امتحان | EQ29: كويز | ER29: امتحان | ES29: كويز | ET29: امتحان | EU29: كويز | EV29: امتحان | EW29: كويز | EX29: امتحان | EY29: كويز | EZ29: امتحان | FA29: كويز | FB29: امتحان | FC29: ملاحظات | FD29: كويز | FE29: امتحان | FF29: كويز | FG29: امتحان | FH29: كويز | FI29: امتحان | FJ29: كويز | FK29: امتحان | FL29: كويز | FM29: امتحان | FN29: كويز | FO29: امتحان | FP29: كويز | FQ29: امتحان | FR29: كويز | FS29: امتحان | FT29: ملاحظات | FU29: كويز | FV29: امتحان | FW29: كويز | FX29: امتحان | FY29: كويز | FZ29: امتحان | GA29: كويز | GB29: امتحان | GC29: كويز | GD29: امتحان | GE29: كويز | GF29: امتحان | GG29: كويز | GH29: امتحان | GI29: كويز | GJ29: امتحان | GK29: ملاحظات | GL29: كويز | GM29: امتحان | GN29: كويز | GO29: امتحان | GP29: كويز | GQ29: امتحان | GR29: كويز | GS29: امتحان | GT29: كويز | GU29: امتحان | GV29: كويز | GW29: امتحان | GX29: كويز | GY29: امتحان | GZ29: كويز | HA29: امتحان | HB29: ملاحظات
A30: 1 | B30: =IF($B5="","",$B5) -> مثال: أحمد محمد علي | C30: =IF(OR($B30="",$HD30=0),"",ROUND($HC30,2)&" / "&$HD30) | D30: =IF(OR($B30="",$HD30=0),"",$HC30/$HD30) | E30: =IF($D30="","",RANK($D30,$D$30:$D$44)) | F30: =IF($D30="","",IF($D30>=0.85,"ممتاز",IF($D30>=0.75,"جيد جداً",IF($D30>=0.65,"جيد",IF($D30>=0.5,"مقبول","ضعيف"))))) | HC30: =SUMIFS($G30:$HB30,$G$46:$HB$46,">="&$HD$1,$G$46:$HB$46,"<="&$HD$2,$G$29:$HB$29,"<>ملاحظات",$G$28:$HB$28,">0") -> 0 | HD30: =SUMIFS($G$28:$HB$28,$G$46:$HB$46,">="&$HD$1,$G$46:$HB$46,"<="&$HD$2,$G$29:$HB$29,"<>ملاحظات",$G30:$HB30,">=0") -> 0
A31: 2 | B31: =IF($B6="","",$B6) | C31: =IF(OR($B31="",$HD31=0),"",ROUND($HC31,2)&" / "&$HD31) | D31: =IF(OR($B31="",$HD31=0),"",$HC31/$HD31) | E31: =IF($D31="","",RANK($D31,$D$30:$D$44)) | F31: =IF($D31="","",IF($D31>=0.85,"ممتاز",IF($D31>=0.75,"جيد جداً",IF($D31>=0.65,"جيد",IF($D31>=0.5,"مقبول","ضعيف"))))) | HC31: =SUMIFS($G31:$HB31,$G$46:$HB$46,">="&$HD$1,$G$46:$HB$46,"<="&$HD$2,$G$29:$HB$29,"<>ملاحظات",$G$28:$HB$28,">0") -> 0 | HD31: =SUMIFS($G$28:$HB$28,$G$46:$HB$46,">="&$HD$1,$G$46:$HB$46,"<="&$HD$2,$G$29:$HB$29,"<>ملاحظات",$G31:$HB31,">=0") -> 0
A32: 3 | B32: =IF($B7="","",$B7) | C32: =IF(OR($B32="",$HD32=0),"",ROUND($HC32,2)&" / "&$HD32) | D32: =IF(OR($B32="",$HD32=0),"",$HC32/$HD32) | E32: =IF($D32="","",RANK($D32,$D$30:$D$44)) | F32: =IF($D32="","",IF($D32>=0.85,"ممتاز",IF($D32>=0.75,"جيد جداً",IF($D32>=0.65,"جيد",IF($D32>=0.5,"مقبول","ضعيف"))))) | HC32: =SUMIFS($G32:$HB32,$G$46:$HB$46,">="&$HD$1,$G$46:$HB$46,"<="&$HD$2,$G$29:$HB$29,"<>ملاحظات",$G$28:$HB$28,">0") -> 0 | HD32: =SUMIFS($G$28:$HB$28,$G$46:$HB$46,">="&$HD$1,$G$46:$HB$46,"<="&$HD$2,$G$29:$HB$29,"<>ملاحظات",$G32:$HB32,">=0") -> 0
A33: 4 | B33: =IF($B8="","",$B8) | C33: =IF(OR($B33="",$HD33=0),"",ROUND($HC33,2)&" / "&$HD33) | D33: =IF(OR($B33="",$HD33=0),"",$HC33/$HD33) | E33: =IF($D33="","",RANK($D33,$D$30:$D$44)) | F33: =IF($D33="","",IF($D33>=0.85,"ممتاز",IF($D33>=0.75,"جيد جداً",IF($D33>=0.65,"جيد",IF($D33>=0.5,"مقبول","ضعيف"))))) | HC33: =SUMIFS($G33:$HB33,$G$46:$HB$46,">="&$HD$1,$G$46:$HB$46,"<="&$HD$2,$G$29:$HB$29,"<>ملاحظات",$G$28:$HB$28,">0") -> 0 | HD33: =SUMIFS($G$28:$HB$28,$G$46:$HB$46,">="&$HD$1,$G$46:$HB$46,"<="&$HD$2,$G$29:$HB$29,"<>ملاحظات",$G33:$HB33,">=0") -> 0
A34: 5 | B34: =IF($B9="","",$B9) | C34: =IF(OR($B34="",$HD34=0),"",ROUND($HC34,2)&" / "&$HD34) | D34: =IF(OR($B34="",$HD34=0),"",$HC34/$HD34) | E34: =IF($D34="","",RANK($D34,$D$30:$D$44)) | F34: =IF($D34="","",IF($D34>=0.85,"ممتاز",IF($D34>=0.75,"جيد جداً",IF($D34>=0.65,"جيد",IF($D34>=0.5,"مقبول","ضعيف"))))) | HC34: =SUMIFS($G34:$HB34,$G$46:$HB$46,">="&$HD$1,$G$46:$HB$46,"<="&$HD$2,$G$29:$HB$29,"<>ملاحظات",$G$28:$HB$28,">0") -> 0 | HD34: =SUMIFS($G$28:$HB$28,$G$46:$HB$46,">="&$HD$1,$G$46:$HB$46,"<="&$HD$2,$G$29:$HB$29,"<>ملاحظات",$G34:$HB34,">=0") -> 0
A35: 6 | B35: =IF($B10="","",$B10) | C35: =IF(OR($B35="",$HD35=0),"",ROUND($HC35,2)&" / "&$HD35) | D35: =IF(OR($B35="",$HD35=0),"",$HC35/$HD35) | E35: =IF($D35="","",RANK($D35,$D$30:$D$44)) | F35: =IF($D35="","",IF($D35>=0.85,"ممتاز",IF($D35>=0.75,"جيد جداً",IF($D35>=0.65,"جيد",IF($D35>=0.5,"مقبول","ضعيف"))))) | HC35: =SUMIFS($G35:$HB35,$G$46:$HB$46,">="&$HD$1,$G$46:$HB$46,"<="&$HD$2,$G$29:$HB$29,"<>ملاحظات",$G$28:$HB$28,">0") -> 0 | HD35: =SUMIFS($G$28:$HB$28,$G$46:$HB$46,">="&$HD$1,$G$46:$HB$46,"<="&$HD$2,$G$29:$HB$29,"<>ملاحظات",$G35:$HB35,">=0") -> 0
A36: 7 | B36: =IF($B11="","",$B11) | C36: =IF(OR($B36="",$HD36=0),"",ROUND($HC36,2)&" / "&$HD36) | D36: =IF(OR($B36="",$HD36=0),"",$HC36/$HD36) | E36: =IF($D36="","",RANK($D36,$D$30:$D$44)) | F36: =IF($D36="","",IF($D36>=0.85,"ممتاز",IF($D36>=0.75,"جيد جداً",IF($D36>=0.65,"جيد",IF($D36>=0.5,"مقبول","ضعيف"))))) | HC36: =SUMIFS($G36:$HB36,$G$46:$HB$46,">="&$HD$1,$G$46:$HB$46,"<="&$HD$2,$G$29:$HB$29,"<>ملاحظات",$G$28:$HB$28,">0") -> 0 | HD36: =SUMIFS($G$28:$HB$28,$G$46:$HB$46,">="&$HD$1,$G$46:$HB$46,"<="&$HD$2,$G$29:$HB$29,"<>ملاحظات",$G36:$HB36,">=0") -> 0
A37: 8 | B37: =IF($B12="","",$B12) | C37: =IF(OR($B37="",$HD37=0),"",ROUND($HC37,2)&" / "&$HD37) | D37: =IF(OR($B37="",$HD37=0),"",$HC37/$HD37) | E37: =IF($D37="","",RANK($D37,$D$30:$D$44)) | F37: =IF($D37="","",IF($D37>=0.85,"ممتاز",IF($D37>=0.75,"جيد جداً",IF($D37>=0.65,"جيد",IF($D37>=0.5,"مقبول","ضعيف"))))) | HC37: =SUMIFS($G37:$HB37,$G$46:$HB$46,">="&$HD$1,$G$46:$HB$46,"<="&$HD$2,$G$29:$HB$29,"<>ملاحظات",$G$28:$HB$28,">0") -> 0 | HD37: =SUMIFS($G$28:$HB$28,$G$46:$HB$46,">="&$HD$1,$G$46:$HB$46,"<="&$HD$2,$G$29:$HB$29,"<>ملاحظات",$G37:$HB37,">=0") -> 0
A38: 9 | B38: =IF($B13="","",$B13) | C38: =IF(OR($B38="",$HD38=0),"",ROUND($HC38,2)&" / "&$HD38) | D38: =IF(OR($B38="",$HD38=0),"",$HC38/$HD38) | E38: =IF($D38="","",RANK($D38,$D$30:$D$44)) | F38: =IF($D38="","",IF($D38>=0.85,"ممتاز",IF($D38>=0.75,"جيد جداً",IF($D38>=0.65,"جيد",IF($D38>=0.5,"مقبول","ضعيف"))))) | HC38: =SUMIFS($G38:$HB38,$G$46:$HB$46,">="&$HD$1,$G$46:$HB$46,"<="&$HD$2,$G$29:$HB$29,"<>ملاحظات",$G$28:$HB$28,">0") -> 0 | HD38: =SUMIFS($G$28:$HB$28,$G$46:$HB$46,">="&$HD$1,$G$46:$HB$46,"<="&$HD$2,$G$29:$HB$29,"<>ملاحظات",$G38:$HB38,">=0") -> 0
A39: 10 | B39: =IF($B14="","",$B14) | C39: =IF(OR($B39="",$HD39=0),"",ROUND($HC39,2)&" / "&$HD39) | D39: =IF(OR($B39="",$HD39=0),"",$HC39/$HD39) | E39: =IF($D39="","",RANK($D39,$D$30:$D$44)) | F39: =IF($D39="","",IF($D39>=0.85,"ممتاز",IF($D39>=0.75,"جيد جداً",IF($D39>=0.65,"جيد",IF($D39>=0.5,"مقبول","ضعيف"))))) | HC39: =SUMIFS($G39:$HB39,$G$46:$HB$46,">="&$HD$1,$G$46:$HB$46,"<="&$HD$2,$G$29:$HB$29,"<>ملاحظات",$G$28:$HB$28,">0") -> 0 | HD39: =SUMIFS($G$28:$HB$28,$G$46:$HB$46,">="&$HD$1,$G$46:$HB$46,"<="&$HD$2,$G$29:$HB$29,"<>ملاحظات",$G39:$HB39,">=0") -> 0
A40: 11 | B40: =IF($B15="","",$B15) | C40: =IF(OR($B40="",$HD40=0),"",ROUND($HC40,2)&" / "&$HD40) | D40: =IF(OR($B40="",$HD40=0),"",$HC40/$HD40) | E40: =IF($D40="","",RANK($D40,$D$30:$D$44)) | F40: =IF($D40="","",IF($D40>=0.85,"ممتاز",IF($D40>=0.75,"جيد جداً",IF($D40>=0.65,"جيد",IF($D40>=0.5,"مقبول","ضعيف"))))) | HC40: =SUMIFS($G40:$HB40,$G$46:$HB$46,">="&$HD$1,$G$46:$HB$46,"<="&$HD$2,$G$29:$HB$29,"<>ملاحظات",$G$28:$HB$28,">0") -> 0 | HD40: =SUMIFS($G$28:$HB$28,$G$46:$HB$46,">="&$HD$1,$G$46:$HB$46,"<="&$HD$2,$G$29:$HB$29,"<>ملاحظات",$G40:$HB40,">=0") -> 0
A41: 12 | B41: =IF($B16="","",$B16) | C41: =IF(OR($B41="",$HD41=0),"",ROUND($HC41,2)&" / "&$HD41) | D41: =IF(OR($B41="",$HD41=0),"",$HC41/$HD41) | E41: =IF($D41="","",RANK($D41,$D$30:$D$44)) | F41: =IF($D41="","",IF($D41>=0.85,"ممتاز",IF($D41>=0.75,"جيد جداً",IF($D41>=0.65,"جيد",IF($D41>=0.5,"مقبول","ضعيف"))))) | HC41: =SUMIFS($G41:$HB41,$G$46:$HB$46,">="&$HD$1,$G$46:$HB$46,"<="&$HD$2,$G$29:$HB$29,"<>ملاحظات",$G$28:$HB$28,">0") -> 0 | HD41: =SUMIFS($G$28:$HB$28,$G$46:$HB$46,">="&$HD$1,$G$46:$HB$46,"<="&$HD$2,$G$29:$HB$29,"<>ملاحظات",$G41:$HB41,">=0") -> 0
... A44: 15 | B44: =IF($B19="","",$B19) | C44: =IF(OR($B44="",$HD44=0),"",ROUND($HC44,2)&" / "&$HD44) | D44: =IF(OR($B44="",$HD44=0),"",$HC44/$HD44) | E44: =IF($D44="","",RANK($D44,$D$30:$D$44)) | F44: =IF($D44="","",IF($D44>=0.85,"ممتاز",IF($D44>=0.75,"جيد جداً",IF($D44>=0.65,"جيد",IF($D44>=0.5,"مقبول","ضعيف"))))) | HC44: =SUMIFS($G44:$HB44,$G$46:$HB$46,">="&$HD$1,$G$46:$HB$46,"<="&$HD$2,$G$29:$HB$29,"<>ملاحظات",$G$28:$HB$28,">0") -> 0 | HD44: =SUMIFS($G$28:$HB$28,$G$46:$HB$46,">="&$HD$1,$G$46:$HB$46,"<="&$HD$2,$G$29:$HB$29,"<>ملاحظات",$G44:$HB44,">=0") -> 0
G46: 1 | H46: 1 | I46: 1 | J46: 1 | K46: 1 | L46: 1 | M46: 1 | N46: 1 | O46: 1 | P46: 1 | Q46: 1 | R46: 1 | S46: 1 | T46: 1 | U46: 1 | V46: 1 | W46: 1 | X46: 2 | Y46: 2 | Z46: 2 | AA46: 2 | AB46: 2 | AC46: 2 | AD46: 2 | AE46: 2 | AF46: 2 | AG46: 2 | AH46: 2 | AI46: 2 | AJ46: 2 | AK46: 2 | AL46: 2 | AM46: 2 | AN46: 2 | AO46: 3 | AP46: 3 | AQ46: 3 | AR46: 3 | AS46: 3 | AT46: 3 | AU46: 3 | AV46: 3 | AW46: 3 | AX46: 3 | AY46: 3 | AZ46: 3 | BA46: 3 | BB46: 3 | BC46: 3 | BD46: 3 | BE46: 3 | BF46: 4 | BG46: 4 | BH46: 4 | BI46: 4 | BJ46: 4 | BK46: 4 | BL46: 4 | BM46: 4 | BN46: 4 | BO46: 4 | BP46: 4 | BQ46: 4 | BR46: 4 | BS46: 4 | BT46: 4 | BU46: 4 | BV46: 4 | BW46: 5 | BX46: 5 | BY46: 5 | BZ46: 5 | CA46: 5 | CB46: 5 | CC46: 5 | CD46: 5 | CE46: 5 | CF46: 5 | CG46: 5 | CH46: 5 | CI46: 5 | CJ46: 5 | CK46: 5 | CL46: 5 | CM46: 5 | CN46: 6 | CO46: 6 | CP46: 6 | CQ46: 6 | CR46: 6 | CS46: 6 | CT46: 6 | CU46: 6 | CV46: 6 | CW46: 6 | CX46: 6 | CY46: 6 | CZ46: 6 | DA46: 6 | DB46: 6 | DC46: 6 | DD46: 6 | DE46: 7 | DF46: 7 | DG46: 7 | DH46: 7 | DI46: 7 | DJ46: 7 | DK46: 7 | DL46: 7 | DM46: 7 | DN46: 7 | DO46: 7 | DP46: 7 | DQ46: 7 | DR46: 7 | DS46: 7 | DT46: 7 | DU46: 7 | DV46: 8 | DW46: 8 | DX46: 8 | DY46: 8 | DZ46: 8 | EA46: 8 | EB46: 8 | EC46: 8 | ED46: 8 | EE46: 8 | EF46: 8 | EG46: 8 | EH46: 8 | EI46: 8 | EJ46: 8 | EK46: 8 | EL46: 8 | EM46: 9 | EN46: 9 | EO46: 9 | EP46: 9 | EQ46: 9 | ER46: 9 | ES46: 9 | ET46: 9 | EU46: 9 | EV46: 9 | EW46: 9 | EX46: 9 | EY46: 9 | EZ46: 9 | FA46: 9 | FB46: 9 | FC46: 9 | FD46: 10 | FE46: 10 | FF46: 10 | FG46: 10 | FH46: 10 | FI46: 10 | FJ46: 10 | FK46: 10 | FL46: 10 | FM46: 10 | FN46: 10 | FO46: 10 | FP46: 10 | FQ46: 10 | FR46: 10 | FS46: 10 | FT46: 10 | FU46: 11 | FV46: 11 | FW46: 11 | FX46: 11 | FY46: 11 | FZ46: 11 | GA46: 11 | GB46: 11 | GC46: 11 | GD46: 11 | GE46: 11 | GF46: 11 | GG46: 11 | GH46: 11 | GI46: 11 | GJ46: 11 | GK46: 11 | GL46: 12 | GM46: 12 | GN46: 12 | GO46: 12 | GP46: 12 | GQ46: 12 | GR46: 12 | GS46: 12 | GT46: 12 | GU46: 12 | GV46: 12 | GW46: 12 | GX46: 12 | GY46: 12 | GZ46: 12 | HA46: 12 | HB46: 12
